INFO:werkzeug: * Running on http://127.0.0.1:5000/ (Press CTRL+C to quit)
DEBUG:root:Engine created!
DEBUG:root:Begin insert DML!
DEBUG:root:DataModelingLanguage begin!
DEBUG:root:dumps
INFO:werkzeug:127.0.0.1 - - [15/Mar/2020 20:05:41] "[31m[1mGET /create_database_dml HTTP/1.1[0m" 409 -
INFO:werkzeug: * Running on http://127.0.0.1:5000/ (Press CTRL+C to quit)
DEBUG:root:Engine created!
DEBUG:root:Begin insert DML!
DEBUG:root:DataModelingLanguage begin!
DEBUG:root:dumps
INFO:werkzeug:127.0.0.1 - - [15/Mar/2020 20:09:33] "[31m[1mGET /create_database_dml HTTP/1.1[0m" 409 -
INFO:werkzeug: * Running on http://127.0.0.1:5000/ (Press CTRL+C to quit)
DEBUG:root:Engine created!
DEBUG:root:Begin insert DML!
DEBUG:root:DataModelingLanguage begin!
DEBUG:root:dumps
DEBUG:root:DataModelingLanguage created!
DEBUG:root:DataModelingLanguage created!
INFO:werkzeug:127.0.0.1 - - [15/Mar/2020 20:24:04] "[37mGET /create_database_dml HTTP/1.1[0m" 200 -
INFO:werkzeug:127.0.0.1 - - [15/Mar/2020 20:26:57] "[37mOPTIONS /bars HTTP/1.1[0m" 200 -
DEBUG:root:Engine created!
DEBUG:root:Unexpected Error 'Cursor' object has no attribute 'beer_connection'
INFO:werkzeug:127.0.0.1 - - [15/Mar/2020 20:26:57] "[31m[1mGET /bars HTTP/1.1[0m" 409 -
DEBUG:root:Engine created!
DEBUG:root:Unexpected Error 'Cursor' object has no attribute 'beer_connection'
INFO:werkzeug:127.0.0.1 - - [15/Mar/2020 20:26:57] "[31m[1mGET /bars HTTP/1.1[0m" 409 -
INFO:werkzeug:127.0.0.1 - - [15/Mar/2020 20:27:02] "[37mOPTIONS /bars HTTP/1.1[0m" 200 -
DEBUG:root:Engine created!
DEBUG:root:Unexpected Error 'Cursor' object has no attribute 'beer_connection'
INFO:werkzeug:127.0.0.1 - - [15/Mar/2020 20:27:02] "[31m[1mGET /bars HTTP/1.1[0m" 409 -
DEBUG:root:Engine created!
DEBUG:root:Unexpected Error 'Cursor' object has no attribute 'beer_connection'
INFO:werkzeug:127.0.0.1 - - [15/Mar/2020 20:27:02] "[31m[1mGET /bars HTTP/1.1[0m" 409 -
INFO:werkzeug: * Running on http://127.0.0.1:5000/ (Press CTRL+C to quit)
INFO:werkzeug:127.0.0.1 - - [15/Mar/2020 20:35:22] "[37mOPTIONS /bars HTTP/1.1[0m" 200 -
DEBUG:root:Engine created!
DEBUG:root:Exception when we try fetch Bars: 'Cursor' object has no attribute 'get_beer_connection'"
DEBUG:root:Unexpected Error 'Cursor' object has no attribute 'get_beer_connection'
INFO:werkzeug:127.0.0.1 - - [15/Mar/2020 20:35:22] "[31m[1mGET /bars HTTP/1.1[0m" 409 -
DEBUG:root:Engine created!
DEBUG:root:Exception when we try fetch Bars: 'Cursor' object has no attribute 'get_beer_connection'"
DEBUG:root:Unexpected Error 'Cursor' object has no attribute 'get_beer_connection'
INFO:werkzeug:127.0.0.1 - - [15/Mar/2020 20:35:22] "[31m[1mGET /bars HTTP/1.1[0m" 409 -
INFO:werkzeug: * Running on http://127.0.0.1:5000/ (Press CTRL+C to quit)
INFO:werkzeug:127.0.0.1 - - [15/Mar/2020 20:38:54] "[37mOPTIONS /bars HTTP/1.1[0m" 200 -
DEBUG:root:Engine created!
DEBUG:root:Unexpected Error 'Cursor' object has no attribute 'get_beer_connection'
INFO:werkzeug:127.0.0.1 - - [15/Mar/2020 20:38:54] "[31m[1mGET /bars HTTP/1.1[0m" 409 -
DEBUG:root:Engine created!
DEBUG:root:Unexpected Error 'Cursor' object has no attribute 'get_beer_connection'
INFO:werkzeug:127.0.0.1 - - [15/Mar/2020 20:38:54] "[31m[1mGET /bars HTTP/1.1[0m" 409 -
INFO:werkzeug: * Running on http://127.0.0.1:5000/ (Press CTRL+C to quit)
INFO:werkzeug:127.0.0.1 - - [15/Mar/2020 20:44:52] "[37mOPTIONS /bars HTTP/1.1[0m" 200 -
DEBUG:root:Engine created!
DEBUG:root:DefaultConnection full
DEBUG:root:Unexpected Error 'Cursor' object has no attribute 'get_beer_connection'
INFO:werkzeug:127.0.0.1 - - [15/Mar/2020 20:44:53] "[31m[1mGET /bars HTTP/1.1[0m" 409 -
DEBUG:root:Engine created!
DEBUG:root:DefaultConnection full
DEBUG:root:Unexpected Error 'Cursor' object has no attribute 'get_beer_connection'
INFO:werkzeug:127.0.0.1 - - [15/Mar/2020 20:44:53] "[31m[1mGET /bars HTTP/1.1[0m" 409 -
INFO:werkzeug: * Running on http://127.0.0.1:5000/ (Press CTRL+C to quit)
INFO:werkzeug:127.0.0.1 - - [15/Mar/2020 20:48:52] "[37mOPTIONS /bars HTTP/1.1[0m" 200 -
DEBUG:root:Engine created!
DEBUG:root:DefaultConnection full
DEBUG:root:Unexpected Error 'Cursor' object has no attribute 'get_beer_connection'
INFO:werkzeug:127.0.0.1 - - [15/Mar/2020 20:48:53] "[31m[1mGET /bars HTTP/1.1[0m" 409 -
DEBUG:root:Engine created!
DEBUG:root:DefaultConnection full
DEBUG:root:Unexpected Error 'Cursor' object has no attribute 'get_beer_connection'
INFO:werkzeug:127.0.0.1 - - [15/Mar/2020 20:48:53] "[31m[1mGET /bars HTTP/1.1[0m" 409 -
INFO:werkzeug: * Running on http://127.0.0.1:5000/ (Press CTRL+C to quit)
DEBUG:root:Engine created!
DEBUG:root:DefaultConnection full
DEBUG:root:Exception when we try fetch Bars: 'Cursor' object has no attribute 'get_beer_connection'"
DEBUG:root:Unexpected Error 'Cursor' object has no attribute 'get_beer_connection'
INFO:werkzeug:127.0.0.1 - - [15/Mar/2020 20:50:26] "[31m[1mGET /bars HTTP/1.1[0m" 409 -
INFO:werkzeug: * Running on http://127.0.0.1:5000/ (Press CTRL+C to quit)
DEBUG:root:Engine created!
DEBUG:root:DefaultConnection full
DEBUG:root:Exception when we try fetch Bars: 'Cursor' object has no attribute 'session'"
DEBUG:root:Unexpected Error 'Cursor' object has no attribute 'get_beer_connection'
INFO:werkzeug:127.0.0.1 - - [15/Mar/2020 20:51:50] "[31m[1mGET /bars HTTP/1.1[0m" 409 -
INFO:werkzeug: * Running on http://127.0.0.1:5000/ (Press CTRL+C to quit)
DEBUG:root:Engine created!
DEBUG:root:DefaultConnection full
DEBUG:root:Exception when we try fetch Bars: 'DefaultConnection' object has no attribute 'session'"
DEBUG:root:Unexpected Error 'Cursor' object has no attribute 'get_beer_connection'
INFO:werkzeug:127.0.0.1 - - [15/Mar/2020 20:52:56] "[31m[1mGET /bars HTTP/1.1[0m" 409 -
INFO:werkzeug: * Running on http://127.0.0.1:5000/ (Press CTRL+C to quit)
DEBUG:root:Engine created!
DEBUG:root:DefaultConnection full
DEBUG:root:Unexpected Error 'Cursor' object has no attribute 'get_beer_connection'
INFO:werkzeug:127.0.0.1 - - [15/Mar/2020 20:55:03] "[31m[1mGET /bars HTTP/1.1[0m" 409 -
INFO:werkzeug: * Running on http://127.0.0.1:5000/ (Press CTRL+C to quit)
DEBUG:root:Engine created!
DEBUG:root:DefaultConnection full
DEBUG:root:Unexpected Error 'Cursor' object has no attribute 'get_beer_connection'
INFO:werkzeug:127.0.0.1 - - [15/Mar/2020 20:56:14] "[31m[1mGET /bars HTTP/1.1[0m" 409 -
INFO:werkzeug: * Running on http://127.0.0.1:5000/ (Press CTRL+C to quit)
DEBUG:root:Engine created!
DEBUG:root:DefaultConnection full
DEBUG:root:Unexpected Error 'Cursor' object has no attribute 'get_beer_connection'
INFO:werkzeug:127.0.0.1 - - [15/Mar/2020 21:00:08] "[31m[1mGET /bars HTTP/1.1[0m" 409 -
INFO:werkzeug: * Running on http://127.0.0.1:5000/ (Press CTRL+C to quit)
DEBUG:root:Engine created!
DEBUG:root:DefaultConnection full
DEBUG:root:Paso bares
INFO:werkzeug:127.0.0.1 - - [15/Mar/2020 21:01:10] "[37mGET /bars HTTP/1.1[0m" 200 -
INFO:werkzeug:127.0.0.1 - - [15/Mar/2020 21:01:23] "[37mOPTIONS /bars HTTP/1.1[0m" 200 -
DEBUG:root:Engine created!
DEBUG:root:DefaultConnection full
DEBUG:root:Paso bares
INFO:werkzeug:127.0.0.1 - - [15/Mar/2020 21:01:24] "[37mGET /bars HTTP/1.1[0m" 200 -
INFO:werkzeug: * Running on http://127.0.0.1:5000/ (Press CTRL+C to quit)
INFO:werkzeug:127.0.0.1 - - [15/Mar/2020 21:02:32] "[37mOPTIONS /bars HTTP/1.1[0m" 200 -
DEBUG:root:Engine created!
DEBUG:root:DefaultConnection full
DEBUG:root:Paso bares
INFO:werkzeug:127.0.0.1 - - [15/Mar/2020 21:02:32] "[37mGET /bars HTTP/1.1[0m" 200 -
DEBUG:root:Engine created!
DEBUG:root:DefaultConnection full
DEBUG:root:Paso bares
INFO:werkzeug:127.0.0.1 - - [15/Mar/2020 21:02:56] "[37mGET /bars HTTP/1.1[0m" 200 -
INFO:werkzeug: * Running on http://127.0.0.1:5000/ (Press CTRL+C to quit)
INFO:werkzeug:127.0.0.1 - - [15/Mar/2020 21:11:21] "[33mGET /climate/save?q=Bogota HTTP/1.1[0m" 404 -
INFO:werkzeug:127.0.0.1 - - [15/Mar/2020 21:11:22] "[33mGET /climate/save?q=Bogota HTTP/1.1[0m" 404 -
INFO:werkzeug:127.0.0.1 - - [15/Mar/2020 21:11:23] "[37mOPTIONS /bars HTTP/1.1[0m" 200 -
DEBUG:root:Engine created!
DEBUG:root:DefaultConnection full
INFO:werkzeug:127.0.0.1 - - [15/Mar/2020 21:11:23] "[33mGET /climate/save?q=Bogota HTTP/1.1[0m" 404 -
DEBUG:root:Paso bares
INFO:werkzeug:127.0.0.1 - - [15/Mar/2020 21:11:23] "[37mGET /bars HTTP/1.1[0m" 200 -
INFO:werkzeug:127.0.0.1 - - [15/Mar/2020 21:11:23] "[33mGET /climate/save?q=Bogota HTTP/1.1[0m" 404 -
INFO:werkzeug:127.0.0.1 - - [15/Mar/2020 21:11:23] "[33mGET /climate/save?q=Bogota HTTP/1.1[0m" 404 -
INFO:werkzeug:127.0.0.1 - - [15/Mar/2020 21:11:23] "[33mGET /climate/save?q=Bogota HTTP/1.1[0m" 404 -
INFO:werkzeug:127.0.0.1 - - [15/Mar/2020 21:11:55] "[33mGET /climate/save?city=Bogota HTTP/1.1[0m" 404 -
INFO:werkzeug:127.0.0.1 - - [15/Mar/2020 21:11:55] "[33mGET /climate/save?city=Bogota HTTP/1.1[0m" 404 -
INFO:werkzeug:127.0.0.1 - - [15/Mar/2020 21:12:30] "[33mGET /climate/weather?city=Bogota HTTP/1.1[0m" 404 -
INFO:werkzeug:127.0.0.1 - - [15/Mar/2020 21:12:30] "[33mGET /climate/weather?city=Bogota HTTP/1.1[0m" 404 -
INFO:werkzeug:127.0.0.1 - - [15/Mar/2020 21:13:24] "[33mGET /climate/weather?city=Bogota HTTP/1.1[0m" 404 -
INFO:werkzeug:127.0.0.1 - - [15/Mar/2020 21:13:25] "[33mGET /climate/weather?city=Bogota HTTP/1.1[0m" 404 -
INFO:werkzeug: * Running on http://127.0.0.1:5000/ (Press CTRL+C to quit)
INFO:werkzeug:127.0.0.1 - - [15/Mar/2020 21:15:11] "[33mGET /climate/weather?city=Bogota HTTP/1.1[0m" 404 -
INFO:werkzeug:127.0.0.1 - - [15/Mar/2020 21:15:11] "[33mGET /climate/weather?city=Bogota HTTP/1.1[0m" 404 -
INFO:werkzeug:127.0.0.1 - - [15/Mar/2020 21:18:15] "[33mGET /climate/weather HTTP/1.1[0m" 404 -
INFO:werkzeug:127.0.0.1 - - [15/Mar/2020 21:18:16] "[33mGET /climate/weather HTTP/1.1[0m" 404 -
INFO:werkzeug:127.0.0.1 - - [15/Mar/2020 21:18:29] "[33mGET /climate/weather?city=Bogota HTTP/1.1[0m" 404 -
INFO:werkzeug:127.0.0.1 - - [15/Mar/2020 21:18:29] "[33mGET /climate/weather?city=Bogota HTTP/1.1[0m" 404 -
INFO:werkzeug: * Running on http://127.0.0.1:5000/ (Press CTRL+C to quit)
DEBUG:root:Unexpected Error Invalid URL 'api.openweathermap.org/data/2.5/weather': No schema supplied. Perhaps you meant http://api.openweathermap.org/data/2.5/weather?
INFO:werkzeug:127.0.0.1 - - [15/Mar/2020 21:22:56] "[31m[1mGET /climate/weather/Bogota HTTP/1.1[0m" 409 -
DEBUG:root:Unexpected Error Invalid URL 'api.openweathermap.org/data/2.5/weather': No schema supplied. Perhaps you meant http://api.openweathermap.org/data/2.5/weather?
INFO:werkzeug:127.0.0.1 - - [15/Mar/2020 21:22:56] "[31m[1mGET /climate/weather/Bogota HTTP/1.1[0m" 409 -
DEBUG:root:Unexpected Error Invalid URL 'api.openweathermap.org/data/2.5/weather': No schema supplied. Perhaps you meant http://api.openweathermap.org/data/2.5/weather?
INFO:werkzeug:127.0.0.1 - - [15/Mar/2020 21:23:53] "[31m[1mGET /climate/weather/Bogota HTTP/1.1[0m" 409 -
DEBUG:root:Unexpected Error Invalid URL 'api.openweathermap.org/data/2.5/weather': No schema supplied. Perhaps you meant http://api.openweathermap.org/data/2.5/weather?
INFO:werkzeug:127.0.0.1 - - [15/Mar/2020 21:23:54] "[31m[1mGET /climate/weather/Bogota HTTP/1.1[0m" 409 -
INFO:werkzeug:127.0.0.1 - - [15/Mar/2020 21:23:55] "[37mOPTIONS /bars HTTP/1.1[0m" 200 -
DEBUG:root:Unexpected Error Invalid URL 'api.openweathermap.org/data/2.5/weather': No schema supplied. Perhaps you meant http://api.openweathermap.org/data/2.5/weather?
INFO:werkzeug:127.0.0.1 - - [15/Mar/2020 21:23:55] "[31m[1mGET /climate/weather/Bogota HTTP/1.1[0m" 409 -
DEBUG:root:Engine created!
DEBUG:root:DefaultConnection full
DEBUG:root:Paso bares
INFO:werkzeug:127.0.0.1 - - [15/Mar/2020 21:23:55] "[37mGET /bars HTTP/1.1[0m" 200 -
DEBUG:root:Unexpected Error Invalid URL 'api.openweathermap.org/data/2.5/weather': No schema supplied. Perhaps you meant http://api.openweathermap.org/data/2.5/weather?
INFO:werkzeug:127.0.0.1 - - [15/Mar/2020 21:23:55] "[31m[1mGET /climate/weather/Bogota HTTP/1.1[0m" 409 -
DEBUG:root:Unexpected Error Invalid URL 'api.openweathermap.org/data/2.5/weather': No schema supplied. Perhaps you meant http://api.openweathermap.org/data/2.5/weather?
INFO:werkzeug:127.0.0.1 - - [15/Mar/2020 21:23:56] "[31m[1mGET /climate/weather/Bogota HTTP/1.1[0m" 409 -
DEBUG:root:Unexpected Error Invalid URL 'api.openweathermap.org/data/2.5/weather': No schema supplied. Perhaps you meant http://api.openweathermap.org/data/2.5/weather?
INFO:werkzeug:127.0.0.1 - - [15/Mar/2020 21:23:56] "[31m[1mGET /climate/weather/Bogota HTTP/1.1[0m" 409 -
INFO:werkzeug: * Running on http://127.0.0.1:5000/ (Press CTRL+C to quit)
DEBUG:urllib3.connectionpool:Starting new HTTP connection (1): api.openweathermap.org:80
DEBUG:urllib3.connectionpool:http://api.openweathermap.org:80 "GET /data/2.5/weather?q=Bogota&units=metric&appid=8cde928e3f9fdc6ce35a4f5d0375ac62 HTTP/1.1" 200 441
INFO:werkzeug:127.0.0.1 - - [15/Mar/2020 21:25:54] "[37mGET /climate/weather/Bogota HTTP/1.1[0m" 200 -
INFO:werkzeug:127.0.0.1 - - [15/Mar/2020 21:26:00] "[37mOPTIONS /bars HTTP/1.1[0m" 200 -
DEBUG:urllib3.connectionpool:Starting new HTTP connection (1): api.openweathermap.org:80
DEBUG:root:Engine created!
DEBUG:root:DefaultConnection full
DEBUG:root:Paso bares
INFO:werkzeug:127.0.0.1 - - [15/Mar/2020 21:26:00] "[37mGET /bars HTTP/1.1[0m" 200 -
DEBUG:urllib3.connectionpool:http://api.openweathermap.org:80 "GET /data/2.5/weather?q=Bogota&units=metric&appid=8cde928e3f9fdc6ce35a4f5d0375ac62 HTTP/1.1" 200 441
INFO:werkzeug:127.0.0.1 - - [15/Mar/2020 21:26:00] "[37mGET /climate/weather/Bogota HTTP/1.1[0m" 200 -
DEBUG:urllib3.connectionpool:Starting new HTTP connection (1): api.openweathermap.org:80
DEBUG:urllib3.connectionpool:http://api.openweathermap.org:80 "GET /data/2.5/weather?q=Bogota&units=metric&appid=8cde928e3f9fdc6ce35a4f5d0375ac62 HTTP/1.1" 200 441
INFO:werkzeug:127.0.0.1 - - [15/Mar/2020 21:26:00] "[37mGET /climate/weather/Bogota HTTP/1.1[0m" 200 -
INFO:werkzeug: * Running on http://127.0.0.1:5000/ (Press CTRL+C to quit)
DEBUG:root:Engine created!
DEBUG:root:DefaultConnection full
DEBUG:root:Paso bares
DEBUG:root:Unexpected Error name '_promotions' is not defined
INFO:werkzeug:127.0.0.1 - - [15/Mar/2020 21:27:39] "[31m[1mGET /bars HTTP/1.1[0m" 409 -
DEBUG:root:Engine created!
DEBUG:root:DefaultConnection full
DEBUG:root:Paso bares
DEBUG:root:Unexpected Error name '_promotions' is not defined
INFO:werkzeug:127.0.0.1 - - [15/Mar/2020 21:27:52] "[31m[1mGET /bars HTTP/1.1[0m" 409 -
INFO:werkzeug: * Running on http://127.0.0.1:5000/ (Press CTRL+C to quit)
DEBUG:root:Engine created!
DEBUG:root:DefaultConnection full
DEBUG:root:Paso bares
INFO:werkzeug:127.0.0.1 - - [15/Mar/2020 21:28:18] "[37mGET /bars HTTP/1.1[0m" 200 -
DEBUG:urllib3.connectionpool:Starting new HTTP connection (1): api.openweathermap.org:80
DEBUG:urllib3.connectionpool:http://api.openweathermap.org:80 "GET /data/2.5/weather?q=Bogota&units=metric&appid=8cde928e3f9fdc6ce35a4f5d0375ac62 HTTP/1.1" 200 441
INFO:werkzeug:127.0.0.1 - - [15/Mar/2020 21:28:30] "[37mGET /climate/weather/Bogota HTTP/1.1[0m" 200 -
INFO:werkzeug:127.0.0.1 - - [15/Mar/2020 21:28:40] "[37mOPTIONS /bars HTTP/1.1[0m" 200 -
DEBUG:urllib3.connectionpool:Starting new HTTP connection (1): api.openweathermap.org:80
DEBUG:root:Engine created!
DEBUG:root:DefaultConnection full
DEBUG:root:Paso bares
INFO:werkzeug:127.0.0.1 - - [15/Mar/2020 21:28:40] "[37mGET /bars HTTP/1.1[0m" 200 -
DEBUG:urllib3.connectionpool:http://api.openweathermap.org:80 "GET /data/2.5/weather?q=Bogota&units=metric&appid=8cde928e3f9fdc6ce35a4f5d0375ac62 HTTP/1.1" 200 441
INFO:werkzeug:127.0.0.1 - - [15/Mar/2020 21:28:40] "[37mGET /climate/weather/Bogota HTTP/1.1[0m" 200 -
DEBUG:root:Engine created!
DEBUG:root:DefaultConnection full
DEBUG:root:Paso bares
INFO:werkzeug:127.0.0.1 - - [15/Mar/2020 21:29:24] "[37mGET /bars HTTP/1.1[0m" 200 -
DEBUG:root:Engine created!
DEBUG:root:DefaultConnection full
DEBUG:root:Paso bares
INFO:werkzeug:127.0.0.1 - - [15/Mar/2020 21:30:07] "[37mGET /bars HTTP/1.1[0m" 200 -
INFO:werkzeug: * Running on http://127.0.0.1:5000/ (Press CTRL+C to quit)
DEBUG:root:Engine created!
DEBUG:root:DefaultConnection full
DEBUG:root:Paso bares
INFO:werkzeug:127.0.0.1 - - [15/Mar/2020 21:30:30] "[37mGET /bars HTTP/1.1[0m" 200 -
INFO:werkzeug: * Running on http://127.0.0.1:5000/ (Press CTRL+C to quit)
DEBUG:root:Engine created!
DEBUG:root:DefaultConnection full
DEBUG:root:Paso bares
INFO:werkzeug:127.0.0.1 - - [15/Mar/2020 21:35:54] "[37mGET /bars HTTP/1.1[0m" 200 -
INFO:werkzeug:127.0.0.1 - - [15/Mar/2020 21:36:13] "[37mOPTIONS /bars HTTP/1.1[0m" 200 -
DEBUG:urllib3.connectionpool:Starting new HTTP connection (1): api.openweathermap.org:80
DEBUG:root:Engine created!
DEBUG:root:DefaultConnection full
DEBUG:urllib3.connectionpool:http://api.openweathermap.org:80 "GET /data/2.5/weather?q=Bogota&units=metric&appid=8cde928e3f9fdc6ce35a4f5d0375ac62 HTTP/1.1" 200 441
INFO:werkzeug:127.0.0.1 - - [15/Mar/2020 21:36:13] "[37mGET /climate/weather/Bogota HTTP/1.1[0m" 200 -
DEBUG:root:Paso bares
INFO:werkzeug:127.0.0.1 - - [15/Mar/2020 21:36:13] "[37mGET /bars HTTP/1.1[0m" 200 -
DEBUG:root:Engine created!
DEBUG:root:DefaultConnection full
INFO:werkzeug:127.0.0.1 - - [15/Mar/2020 21:39:22] "[37mGET /beers HTTP/1.1[0m" 200 -
INFO:werkzeug:127.0.0.1 - - [15/Mar/2020 21:39:39] "[37mOPTIONS /beer/null/GET HTTP/1.1[0m" 200 -
DEBUG:urllib3.connectionpool:Starting new HTTP connection (1): api.openweathermap.org:80
DEBUG:root:Engine created!
DEBUG:root:DefaultConnection full
DEBUG:root:Unexpected Error (psycopg2.errors.InvalidTextRepresentation) invalid input syntax for type integer: "null"
LINE 3: WHERE public."BEER".id = 'null'
                                 ^

[SQL: SELECT public."BEER".created_at AS "public_BEER_created_at", public."BEER".updated_at AS "public_BEER_updated_at", public."BEER".last_updated_by AS "public_BEER_last_updated_by", public."BEER".id AS "public_BEER_id", public."BEER".name AS "public_BEER_name", public."BEER".pint_price AS "public_BEER_pint_price", public."BEER".cup330_price AS "public_BEER_cup330_price", public."BEER".giraffe_price AS "public_BEER_giraffe_price", public."BEER".pitcher_price AS "public_BEER_pitcher_price", public."BEER".bar_id AS "public_BEER_bar_id", public."BEER".beer_type_id AS "public_BEER_beer_type_id", public."BEER".avb AS "public_BEER_avb", public."BEER".ibu AS "public_BEER_ibu", public."BEER".srm AS "public_BEER_srm", public."BEER".description AS "public_BEER_description", public."BEER".image AS "public_BEER_image", public."BEER".pint AS "public_BEER_pint", public."BEER".cup330 AS "public_BEER_cup330", public."BEER".giraffe AS "public_BEER_giraffe", public."BEER".pitcher AS "public_BEER_pitcher" 
FROM public."BEER" 
WHERE public."BEER".id = %(id_1)s]
[parameters: {'id_1': 'null'}]
(Background on this error at: http://sqlalche.me/e/9h9h)
INFO:werkzeug:127.0.0.1 - - [15/Mar/2020 21:39:39] "[31m[1mGET /beer/null/GET HTTP/1.1[0m" 409 -
DEBUG:root:Engine created!
DEBUG:root:DefaultConnection full
DEBUG:urllib3.connectionpool:http://api.openweathermap.org:80 "GET /data/2.5/weather?q=Bogota&units=metric&appid=8cde928e3f9fdc6ce35a4f5d0375ac62 HTTP/1.1" 200 441
INFO:werkzeug:127.0.0.1 - - [15/Mar/2020 21:39:40] "[37mGET /climate/weather/Bogota HTTP/1.1[0m" 200 -
DEBUG:root:Unexpected Error (psycopg2.errors.InvalidTextRepresentation) invalid input syntax for type integer: "null"
LINE 3: WHERE public."BEER".id = 'null'
                                 ^

[SQL: SELECT public."BEER".created_at AS "public_BEER_created_at", public."BEER".updated_at AS "public_BEER_updated_at", public."BEER".last_updated_by AS "public_BEER_last_updated_by", public."BEER".id AS "public_BEER_id", public."BEER".name AS "public_BEER_name", public."BEER".pint_price AS "public_BEER_pint_price", public."BEER".cup330_price AS "public_BEER_cup330_price", public."BEER".giraffe_price AS "public_BEER_giraffe_price", public."BEER".pitcher_price AS "public_BEER_pitcher_price", public."BEER".bar_id AS "public_BEER_bar_id", public."BEER".beer_type_id AS "public_BEER_beer_type_id", public."BEER".avb AS "public_BEER_avb", public."BEER".ibu AS "public_BEER_ibu", public."BEER".srm AS "public_BEER_srm", public."BEER".description AS "public_BEER_description", public."BEER".image AS "public_BEER_image", public."BEER".pint AS "public_BEER_pint", public."BEER".cup330 AS "public_BEER_cup330", public."BEER".giraffe AS "public_BEER_giraffe", public."BEER".pitcher AS "public_BEER_pitcher" 
FROM public."BEER" 
WHERE public."BEER".id = %(id_1)s]
[parameters: {'id_1': 'null'}]
(Background on this error at: http://sqlalche.me/e/9h9h)
INFO:werkzeug:127.0.0.1 - - [15/Mar/2020 21:39:40] "[31m[1mGET /beer/null/GET HTTP/1.1[0m" 409 -
INFO:werkzeug:127.0.0.1 - - [15/Mar/2020 22:09:27] "[37mOPTIONS /beer/null/GET HTTP/1.1[0m" 200 -
DEBUG:urllib3.connectionpool:Starting new HTTP connection (1): api.openweathermap.org:80
DEBUG:root:Engine created!
DEBUG:root:DefaultConnection full
DEBUG:root:Unexpected Error (psycopg2.errors.InvalidTextRepresentation) invalid input syntax for type integer: "null"
LINE 3: WHERE public."BEER".id = 'null'
                                 ^

[SQL: SELECT public."BEER".created_at AS "public_BEER_created_at", public."BEER".updated_at AS "public_BEER_updated_at", public."BEER".last_updated_by AS "public_BEER_last_updated_by", public."BEER".id AS "public_BEER_id", public."BEER".name AS "public_BEER_name", public."BEER".pint_price AS "public_BEER_pint_price", public."BEER".cup330_price AS "public_BEER_cup330_price", public."BEER".giraffe_price AS "public_BEER_giraffe_price", public."BEER".pitcher_price AS "public_BEER_pitcher_price", public."BEER".bar_id AS "public_BEER_bar_id", public."BEER".beer_type_id AS "public_BEER_beer_type_id", public."BEER".avb AS "public_BEER_avb", public."BEER".ibu AS "public_BEER_ibu", public."BEER".srm AS "public_BEER_srm", public."BEER".description AS "public_BEER_description", public."BEER".image AS "public_BEER_image", public."BEER".pint AS "public_BEER_pint", public."BEER".cup330 AS "public_BEER_cup330", public."BEER".giraffe AS "public_BEER_giraffe", public."BEER".pitcher AS "public_BEER_pitcher" 
FROM public."BEER" 
WHERE public."BEER".id = %(id_1)s]
[parameters: {'id_1': 'null'}]
(Background on this error at: http://sqlalche.me/e/9h9h)
INFO:werkzeug:127.0.0.1 - - [15/Mar/2020 22:09:28] "[31m[1mGET /beer/null/GET HTTP/1.1[0m" 409 -
DEBUG:root:Engine created!
DEBUG:root:DefaultConnection full
DEBUG:root:Unexpected Error (psycopg2.errors.InvalidTextRepresentation) invalid input syntax for type integer: "null"
LINE 3: WHERE public."BEER".id = 'null'
                                 ^

[SQL: SELECT public."BEER".created_at AS "public_BEER_created_at", public."BEER".updated_at AS "public_BEER_updated_at", public."BEER".last_updated_by AS "public_BEER_last_updated_by", public."BEER".id AS "public_BEER_id", public."BEER".name AS "public_BEER_name", public."BEER".pint_price AS "public_BEER_pint_price", public."BEER".cup330_price AS "public_BEER_cup330_price", public."BEER".giraffe_price AS "public_BEER_giraffe_price", public."BEER".pitcher_price AS "public_BEER_pitcher_price", public."BEER".bar_id AS "public_BEER_bar_id", public."BEER".beer_type_id AS "public_BEER_beer_type_id", public."BEER".avb AS "public_BEER_avb", public."BEER".ibu AS "public_BEER_ibu", public."BEER".srm AS "public_BEER_srm", public."BEER".description AS "public_BEER_description", public."BEER".image AS "public_BEER_image", public."BEER".pint AS "public_BEER_pint", public."BEER".cup330 AS "public_BEER_cup330", public."BEER".giraffe AS "public_BEER_giraffe", public."BEER".pitcher AS "public_BEER_pitcher" 
FROM public."BEER" 
WHERE public."BEER".id = %(id_1)s]
[parameters: {'id_1': 'null'}]
(Background on this error at: http://sqlalche.me/e/9h9h)
INFO:werkzeug:127.0.0.1 - - [15/Mar/2020 22:09:28] "[31m[1mGET /beer/null/GET HTTP/1.1[0m" 409 -
DEBUG:urllib3.connectionpool:http://api.openweathermap.org:80 "GET /data/2.5/weather?q=Bogota&units=metric&appid=8cde928e3f9fdc6ce35a4f5d0375ac62 HTTP/1.1" 200 441
INFO:werkzeug:127.0.0.1 - - [15/Mar/2020 22:09:29] "[37mGET /climate/weather/Bogota HTTP/1.1[0m" 200 -
INFO:werkzeug:127.0.0.1 - - [16/Mar/2020 09:43:52] "[37mOPTIONS /beer/null/GET HTTP/1.1[0m" 200 -
DEBUG:urllib3.connectionpool:Starting new HTTP connection (1): api.openweathermap.org:80
DEBUG:root:Unexpected Error HTTPConnectionPool(host='api.openweathermap.org', port=80): Max retries exceeded with url: /data/2.5/weather?q=Bogota&units=metric&appid=8cde928e3f9fdc6ce35a4f5d0375ac62 (Caused by NewConnectionError('<urllib3.connection.HTTPConnection object at 0x051D7658>: Failed to establish a new connection: [Errno 11001] getaddrinfo failed'))
INFO:werkzeug:127.0.0.1 - - [16/Mar/2020 09:43:52] "[31m[1mGET /climate/weather/Bogota HTTP/1.1[0m" 409 -
DEBUG:root:Engine created!
DEBUG:root:DefaultConnection full
DEBUG:urllib3.connectionpool:Starting new HTTP connection (1): api.openweathermap.org:80
DEBUG:root:Unexpected Error HTTPConnectionPool(host='api.openweathermap.org', port=80): Max retries exceeded with url: /data/2.5/weather?q=Bogota&units=metric&appid=8cde928e3f9fdc6ce35a4f5d0375ac62 (Caused by NewConnectionError('<urllib3.connection.HTTPConnection object at 0x045D9C70>: Failed to establish a new connection: [Errno 11001] getaddrinfo failed'))
INFO:werkzeug:127.0.0.1 - - [16/Mar/2020 09:43:53] "[31m[1mGET /climate/weather/Bogota HTTP/1.1[0m" 409 -
DEBUG:root:Unexpected Error (psycopg2.errors.InvalidTextRepresentation) invalid input syntax for type integer: "null"
LINE 3: WHERE public."BEER".id = 'null'
                                 ^

[SQL: SELECT public."BEER".created_at AS "public_BEER_created_at", public."BEER".updated_at AS "public_BEER_updated_at", public."BEER".last_updated_by AS "public_BEER_last_updated_by", public."BEER".id AS "public_BEER_id", public."BEER".name AS "public_BEER_name", public."BEER".pint_price AS "public_BEER_pint_price", public."BEER".cup330_price AS "public_BEER_cup330_price", public."BEER".giraffe_price AS "public_BEER_giraffe_price", public."BEER".pitcher_price AS "public_BEER_pitcher_price", public."BEER".bar_id AS "public_BEER_bar_id", public."BEER".beer_type_id AS "public_BEER_beer_type_id", public."BEER".avb AS "public_BEER_avb", public."BEER".ibu AS "public_BEER_ibu", public."BEER".srm AS "public_BEER_srm", public."BEER".description AS "public_BEER_description", public."BEER".image AS "public_BEER_image", public."BEER".pint AS "public_BEER_pint", public."BEER".cup330 AS "public_BEER_cup330", public."BEER".giraffe AS "public_BEER_giraffe", public."BEER".pitcher AS "public_BEER_pitcher" 
FROM public."BEER" 
WHERE public."BEER".id = %(id_1)s]
[parameters: {'id_1': 'null'}]
(Background on this error at: http://sqlalche.me/e/9h9h)
INFO:werkzeug:127.0.0.1 - - [16/Mar/2020 09:43:53] "[31m[1mGET /beer/null/GET HTTP/1.1[0m" 409 -
DEBUG:root:Engine created!
DEBUG:root:DefaultConnection full
DEBUG:root:Unexpected Error (psycopg2.errors.InvalidTextRepresentation) invalid input syntax for type integer: "null"
LINE 3: WHERE public."BEER".id = 'null'
                                 ^

[SQL: SELECT public."BEER".created_at AS "public_BEER_created_at", public."BEER".updated_at AS "public_BEER_updated_at", public."BEER".last_updated_by AS "public_BEER_last_updated_by", public."BEER".id AS "public_BEER_id", public."BEER".name AS "public_BEER_name", public."BEER".pint_price AS "public_BEER_pint_price", public."BEER".cup330_price AS "public_BEER_cup330_price", public."BEER".giraffe_price AS "public_BEER_giraffe_price", public."BEER".pitcher_price AS "public_BEER_pitcher_price", public."BEER".bar_id AS "public_BEER_bar_id", public."BEER".beer_type_id AS "public_BEER_beer_type_id", public."BEER".avb AS "public_BEER_avb", public."BEER".ibu AS "public_BEER_ibu", public."BEER".srm AS "public_BEER_srm", public."BEER".description AS "public_BEER_description", public."BEER".image AS "public_BEER_image", public."BEER".pint AS "public_BEER_pint", public."BEER".cup330 AS "public_BEER_cup330", public."BEER".giraffe AS "public_BEER_giraffe", public."BEER".pitcher AS "public_BEER_pitcher" 
FROM public."BEER" 
WHERE public."BEER".id = %(id_1)s]
[parameters: {'id_1': 'null'}]
(Background on this error at: http://sqlalche.me/e/9h9h)
INFO:werkzeug:127.0.0.1 - - [16/Mar/2020 09:43:53] "[31m[1mGET /beer/null/GET HTTP/1.1[0m" 409 -
INFO:werkzeug: * Running on http://127.0.0.1:5000/ (Press CTRL+C to quit)
INFO:werkzeug:127.0.0.1 - - [12/Apr/2020 15:00:25] "[37mGET /spec HTTP/1.1[0m" 200 -
INFO:werkzeug:127.0.0.1 - - [12/Apr/2020 15:00:25] "[33mGET /favicon.ico HTTP/1.1[0m" 404 -
INFO:werkzeug: * Running on http://127.0.0.1:5000/ (Press CTRL+C to quit)
INFO:werkzeug:127.0.0.1 - - [12/Apr/2020 15:01:47] "[37mGET /spec HTTP/1.1[0m" 200 -
INFO:werkzeug: * Running on http://127.0.0.1:5000/ (Press CTRL+C to quit)
INFO:werkzeug:127.0.0.1 - - [12/Apr/2020 15:19:22] "GET / HTTP/1.1" 200 -
INFO:werkzeug:127.0.0.1 - - [12/Apr/2020 15:19:22] "GET /swaggerui/droid-sans.css HTTP/1.1" 200 -
INFO:werkzeug:127.0.0.1 - - [12/Apr/2020 15:19:23] "GET /swaggerui/swagger-ui.css HTTP/1.1" 200 -
INFO:werkzeug:127.0.0.1 - - [12/Apr/2020 15:19:23] "GET /swaggerui/swagger-ui-standalone-preset.js HTTP/1.1" 200 -
INFO:werkzeug:127.0.0.1 - - [12/Apr/2020 15:19:24] "GET /swaggerui/swagger-ui-bundle.js HTTP/1.1" 200 -
INFO:werkzeug:127.0.0.1 - - [12/Apr/2020 15:19:24] "GET /swagger.json HTTP/1.1" 200 -
INFO:werkzeug:127.0.0.1 - - [12/Apr/2020 15:19:24] "GET /swaggerui/favicon-32x32.png HTTP/1.1" 200 -
INFO:werkzeug:127.0.0.1 - - [12/Apr/2020 15:19:27] "GET /swagger.json HTTP/1.1" 200 -
INFO:werkzeug: * Running on http://127.0.0.1:5000/ (Press CTRL+C to quit)
ERROR:servicio:Exception on /spec [GET]
Traceback (most recent call last):
  File "C:\Users\alejo\Documents\Work\Personal\BeerAPP\invitame_una_cerveza\Python\env\lib\site-packages\flask\app.py", line 2446, in wsgi_app
    response = self.full_dispatch_request()
  File "C:\Users\alejo\Documents\Work\Personal\BeerAPP\invitame_una_cerveza\Python\env\lib\site-packages\flask\app.py", line 1951, in full_dispatch_request
    rv = self.handle_user_exception(e)
  File "C:\Users\alejo\Documents\Work\Personal\BeerAPP\invitame_una_cerveza\Python\env\lib\site-packages\flask_cors\extension.py", line 161, in wrapped_function
    return cors_after_request(app.make_response(f(*args, **kwargs)))
  File "C:\Users\alejo\Documents\Work\Personal\BeerAPP\invitame_una_cerveza\Python\env\lib\site-packages\flask\app.py", line 1820, in handle_user_exception
    reraise(exc_type, exc_value, tb)
  File "C:\Users\alejo\Documents\Work\Personal\BeerAPP\invitame_una_cerveza\Python\env\lib\site-packages\flask\_compat.py", line 39, in reraise
    raise value
  File "C:\Users\alejo\Documents\Work\Personal\BeerAPP\invitame_una_cerveza\Python\env\lib\site-packages\flask\app.py", line 1949, in full_dispatch_request
    rv = self.dispatch_request()
  File "C:\Users\alejo\Documents\Work\Personal\BeerAPP\invitame_una_cerveza\Python\env\lib\site-packages\flask\app.py", line 1935, in dispatch_request
    return self.view_functions[rule.endpoint](**req.view_args)
  File "C:\Users\alejo\Documents\Work\Personal\BeerAPP\invitame_una_cerveza\Python\env\lib\site-packages\flask_cors\decorator.py", line 128, in wrapped_function
    resp = make_response(f(*args, **kwargs))
  File "servicio.py", line 430, in spec
    swag = swagger(app)
  File "C:\Users\alejo\Documents\Work\Personal\BeerAPP\invitame_una_cerveza\Python\env\lib\site-packages\flask_swagger.py", line 183, in swagger
    summary, description, swag = _parse_docstring(method, process_doc,
  File "C:\Users\alejo\Documents\Work\Personal\BeerAPP\invitame_una_cerveza\Python\env\lib\site-packages\flask_swagger.py", line 63, in _parse_docstring
    swag = yaml.full_load(full_doc[line_feed+yaml_sep:])
  File "C:\Users\alejo\Documents\Work\Personal\BeerAPP\invitame_una_cerveza\Python\env\lib\site-packages\yaml\__init__.py", line 142, in full_load
    return load(stream, FullLoader)
  File "C:\Users\alejo\Documents\Work\Personal\BeerAPP\invitame_una_cerveza\Python\env\lib\site-packages\yaml\__init__.py", line 114, in load
    return loader.get_single_data()
  File "C:\Users\alejo\Documents\Work\Personal\BeerAPP\invitame_una_cerveza\Python\env\lib\site-packages\yaml\constructor.py", line 49, in get_single_data
    node = self.get_single_node()
  File "C:\Users\alejo\Documents\Work\Personal\BeerAPP\invitame_una_cerveza\Python\env\lib\site-packages\yaml\composer.py", line 36, in get_single_node
    document = self.compose_document()
  File "C:\Users\alejo\Documents\Work\Personal\BeerAPP\invitame_una_cerveza\Python\env\lib\site-packages\yaml\composer.py", line 55, in compose_document
    node = self.compose_node(None, None)
  File "C:\Users\alejo\Documents\Work\Personal\BeerAPP\invitame_una_cerveza\Python\env\lib\site-packages\yaml\composer.py", line 84, in compose_node
    node = self.compose_mapping_node(anchor)
  File "C:\Users\alejo\Documents\Work\Personal\BeerAPP\invitame_una_cerveza\Python\env\lib\site-packages\yaml\composer.py", line 133, in compose_mapping_node
    item_value = self.compose_node(node, item_key)
  File "C:\Users\alejo\Documents\Work\Personal\BeerAPP\invitame_una_cerveza\Python\env\lib\site-packages\yaml\composer.py", line 82, in compose_node
    node = self.compose_sequence_node(anchor)
  File "C:\Users\alejo\Documents\Work\Personal\BeerAPP\invitame_una_cerveza\Python\env\lib\site-packages\yaml\composer.py", line 110, in compose_sequence_node
    while not self.check_event(SequenceEndEvent):
  File "C:\Users\alejo\Documents\Work\Personal\BeerAPP\invitame_una_cerveza\Python\env\lib\site-packages\yaml\parser.py", line 98, in check_event
    self.current_event = self.state()
  File "C:\Users\alejo\Documents\Work\Personal\BeerAPP\invitame_una_cerveza\Python\env\lib\site-packages\yaml\parser.py", line 382, in parse_block_sequence_entry
    if self.check_token(BlockEntryToken):
  File "C:\Users\alejo\Documents\Work\Personal\BeerAPP\invitame_una_cerveza\Python\env\lib\site-packages\yaml\scanner.py", line 116, in check_token
    self.fetch_more_tokens()
  File "C:\Users\alejo\Documents\Work\Personal\BeerAPP\invitame_una_cerveza\Python\env\lib\site-packages\yaml\scanner.py", line 223, in fetch_more_tokens
    return self.fetch_value()
  File "C:\Users\alejo\Documents\Work\Personal\BeerAPP\invitame_una_cerveza\Python\env\lib\site-packages\yaml\scanner.py", line 577, in fetch_value
    raise ScannerError(None, None,
yaml.scanner.ScannerError: mapping values are not allowed here
  in "<unicode string>", line 5, column 16:
        definitions:
                   ^
INFO:werkzeug:127.0.0.1 - - [12/Apr/2020 15:49:46] "GET /spec HTTP/1.1" 500 -
INFO:werkzeug: * Running on http://127.0.0.1:5000/ (Press CTRL+C to quit)
ERROR:servicio:Exception on /spec [GET]
Traceback (most recent call last):
  File "C:\Users\alejo\Documents\Work\Personal\BeerAPP\invitame_una_cerveza\Python\env\lib\site-packages\flask\app.py", line 2446, in wsgi_app
    response = self.full_dispatch_request()
  File "C:\Users\alejo\Documents\Work\Personal\BeerAPP\invitame_una_cerveza\Python\env\lib\site-packages\flask\app.py", line 1951, in full_dispatch_request
    rv = self.handle_user_exception(e)
  File "C:\Users\alejo\Documents\Work\Personal\BeerAPP\invitame_una_cerveza\Python\env\lib\site-packages\flask_cors\extension.py", line 161, in wrapped_function
    return cors_after_request(app.make_response(f(*args, **kwargs)))
  File "C:\Users\alejo\Documents\Work\Personal\BeerAPP\invitame_una_cerveza\Python\env\lib\site-packages\flask\app.py", line 1820, in handle_user_exception
    reraise(exc_type, exc_value, tb)
  File "C:\Users\alejo\Documents\Work\Personal\BeerAPP\invitame_una_cerveza\Python\env\lib\site-packages\flask\_compat.py", line 39, in reraise
    raise value
  File "C:\Users\alejo\Documents\Work\Personal\BeerAPP\invitame_una_cerveza\Python\env\lib\site-packages\flask\app.py", line 1949, in full_dispatch_request
    rv = self.dispatch_request()
  File "C:\Users\alejo\Documents\Work\Personal\BeerAPP\invitame_una_cerveza\Python\env\lib\site-packages\flask\app.py", line 1935, in dispatch_request
    return self.view_functions[rule.endpoint](**req.view_args)
  File "C:\Users\alejo\Documents\Work\Personal\BeerAPP\invitame_una_cerveza\Python\env\lib\site-packages\flask_cors\decorator.py", line 128, in wrapped_function
    resp = make_response(f(*args, **kwargs))
  File "servicio.py", line 430, in spec
    swag = swagger(app)
  File "C:\Users\alejo\Documents\Work\Personal\BeerAPP\invitame_una_cerveza\Python\env\lib\site-packages\flask_swagger.py", line 183, in swagger
    summary, description, swag = _parse_docstring(method, process_doc,
  File "C:\Users\alejo\Documents\Work\Personal\BeerAPP\invitame_una_cerveza\Python\env\lib\site-packages\flask_swagger.py", line 63, in _parse_docstring
    swag = yaml.full_load(full_doc[line_feed+yaml_sep:])
  File "C:\Users\alejo\Documents\Work\Personal\BeerAPP\invitame_una_cerveza\Python\env\lib\site-packages\yaml\__init__.py", line 142, in full_load
    return load(stream, FullLoader)
  File "C:\Users\alejo\Documents\Work\Personal\BeerAPP\invitame_una_cerveza\Python\env\lib\site-packages\yaml\__init__.py", line 114, in load
    return loader.get_single_data()
  File "C:\Users\alejo\Documents\Work\Personal\BeerAPP\invitame_una_cerveza\Python\env\lib\site-packages\yaml\constructor.py", line 49, in get_single_data
    node = self.get_single_node()
  File "C:\Users\alejo\Documents\Work\Personal\BeerAPP\invitame_una_cerveza\Python\env\lib\site-packages\yaml\composer.py", line 36, in get_single_node
    document = self.compose_document()
  File "C:\Users\alejo\Documents\Work\Personal\BeerAPP\invitame_una_cerveza\Python\env\lib\site-packages\yaml\composer.py", line 55, in compose_document
    node = self.compose_node(None, None)
  File "C:\Users\alejo\Documents\Work\Personal\BeerAPP\invitame_una_cerveza\Python\env\lib\site-packages\yaml\composer.py", line 84, in compose_node
    node = self.compose_mapping_node(anchor)
  File "C:\Users\alejo\Documents\Work\Personal\BeerAPP\invitame_una_cerveza\Python\env\lib\site-packages\yaml\composer.py", line 133, in compose_mapping_node
    item_value = self.compose_node(node, item_key)
  File "C:\Users\alejo\Documents\Work\Personal\BeerAPP\invitame_una_cerveza\Python\env\lib\site-packages\yaml\composer.py", line 82, in compose_node
    node = self.compose_sequence_node(anchor)
  File "C:\Users\alejo\Documents\Work\Personal\BeerAPP\invitame_una_cerveza\Python\env\lib\site-packages\yaml\composer.py", line 111, in compose_sequence_node
    node.value.append(self.compose_node(node, index))
  File "C:\Users\alejo\Documents\Work\Personal\BeerAPP\invitame_una_cerveza\Python\env\lib\site-packages\yaml\composer.py", line 84, in compose_node
    node = self.compose_mapping_node(anchor)
  File "C:\Users\alejo\Documents\Work\Personal\BeerAPP\invitame_una_cerveza\Python\env\lib\site-packages\yaml\composer.py", line 133, in compose_mapping_node
    item_value = self.compose_node(node, item_key)
  File "C:\Users\alejo\Documents\Work\Personal\BeerAPP\invitame_una_cerveza\Python\env\lib\site-packages\yaml\composer.py", line 84, in compose_node
    node = self.compose_mapping_node(anchor)
  File "C:\Users\alejo\Documents\Work\Personal\BeerAPP\invitame_una_cerveza\Python\env\lib\site-packages\yaml\composer.py", line 127, in compose_mapping_node
    while not self.check_event(MappingEndEvent):
  File "C:\Users\alejo\Documents\Work\Personal\BeerAPP\invitame_una_cerveza\Python\env\lib\site-packages\yaml\parser.py", line 98, in check_event
    self.current_event = self.state()
  File "C:\Users\alejo\Documents\Work\Personal\BeerAPP\invitame_una_cerveza\Python\env\lib\site-packages\yaml\parser.py", line 428, in parse_block_mapping_key
    if self.check_token(KeyToken):
  File "C:\Users\alejo\Documents\Work\Personal\BeerAPP\invitame_una_cerveza\Python\env\lib\site-packages\yaml\scanner.py", line 116, in check_token
    self.fetch_more_tokens()
  File "C:\Users\alejo\Documents\Work\Personal\BeerAPP\invitame_una_cerveza\Python\env\lib\site-packages\yaml\scanner.py", line 223, in fetch_more_tokens
    return self.fetch_value()
  File "C:\Users\alejo\Documents\Work\Personal\BeerAPP\invitame_una_cerveza\Python\env\lib\site-packages\yaml\scanner.py", line 577, in fetch_value
    raise ScannerError(None, None,
yaml.scanner.ScannerError: mapping values are not allowed here
  in "<unicode string>", line 17, column 19:
              required:
                      ^
INFO:werkzeug:127.0.0.1 - - [12/Apr/2020 15:51:33] "GET /spec HTTP/1.1" 500 -
INFO:werkzeug: * Running on http://127.0.0.1:5000/ (Press CTRL+C to quit)
INFO:werkzeug:127.0.0.1 - - [12/Apr/2020 15:54:10] "GET /spec HTTP/1.1" 200 -
INFO:werkzeug: * Running on http://127.0.0.1:5000/ (Press CTRL+C to quit)
DEBUG:urllib3.connectionpool:Starting new HTTP connection (1): api.openweathermap.org:80
DEBUG:urllib3.connectionpool:http://api.openweathermap.org:80 "GET /data/2.5/weather?q=Bogota&units=metric&appid=8cde928e3f9fdc6ce35a4f5d0375ac62 HTTP/1.1" 200 460
INFO:werkzeug:127.0.0.1 - - [12/Apr/2020 16:21:35] "GET /climate/weather/Bogota HTTP/1.1" 200 -
DEBUG:urllib3.connectionpool:Starting new HTTP connection (1): api.openweathermap.org:80
DEBUG:urllib3.connectionpool:http://api.openweathermap.org:80 "GET /data/2.5/weather?q=Bogota&units=metric&appid=8cde928e3f9fdc6ce35a4f5d0375ac62 HTTP/1.1" 200 460
INFO:werkzeug:127.0.0.1 - - [12/Apr/2020 16:21:38] "GET /climate/weather/Bogota HTTP/1.1" 200 -
INFO:werkzeug:127.0.0.1 - - [12/Apr/2020 16:21:40] "OPTIONS /bars HTTP/1.1" 200 -
DEBUG:urllib3.connectionpool:Starting new HTTP connection (1): api.openweathermap.org:80
DEBUG:root:Engine created!
DEBUG:root:DefaultConnection full
DEBUG:urllib3.connectionpool:http://api.openweathermap.org:80 "GET /data/2.5/weather?q=Bogota&units=metric&appid=8cde928e3f9fdc6ce35a4f5d0375ac62 HTTP/1.1" 200 460
INFO:werkzeug:127.0.0.1 - - [12/Apr/2020 16:21:41] "GET /climate/weather/Bogota HTTP/1.1" 200 -
DEBUG:root:Exception when we try fetch Bars: (psycopg2.OperationalError) FATAL:  database "invitame_una_cerveza" does not exist

(Background on this error at: http://sqlalche.me/e/e3q8)"
DEBUG:root:Paso bares
DEBUG:root:Unexpected Error object of type 'NoneType' has no len()
INFO:werkzeug:127.0.0.1 - - [12/Apr/2020 16:21:41] "GET /bars HTTP/1.1" 409 -
DEBUG:root:Engine created!
DEBUG:root:DefaultConnection full
DEBUG:root:Exception when we try fetch Bars: (psycopg2.OperationalError) FATAL:  database "invitame_una_cerveza" does not exist

(Background on this error at: http://sqlalche.me/e/e3q8)"
DEBUG:root:Paso bares
DEBUG:root:Unexpected Error object of type 'NoneType' has no len()
INFO:werkzeug:127.0.0.1 - - [12/Apr/2020 16:21:41] "GET /bars HTTP/1.1" 409 -
DEBUG:urllib3.connectionpool:Starting new HTTP connection (1): api.openweathermap.org:80
DEBUG:urllib3.connectionpool:http://api.openweathermap.org:80 "GET /data/2.5/weather?q=Bogota&units=metric&appid=8cde928e3f9fdc6ce35a4f5d0375ac62 HTTP/1.1" 200 460
INFO:werkzeug:127.0.0.1 - - [12/Apr/2020 16:21:42] "GET /climate/weather/Bogota HTTP/1.1" 200 -
DEBUG:root:Engine created!
DEBUG:root:DefaultConnection full
DEBUG:root:Exception when we try fetch Bars: (psycopg2.OperationalError) FATAL:  database "invitame_una_cerveza" does not exist

(Background on this error at: http://sqlalche.me/e/e3q8)"
DEBUG:root:Paso bares
DEBUG:root:Unexpected Error object of type 'NoneType' has no len()
INFO:werkzeug:127.0.0.1 - - [12/Apr/2020 16:22:15] "GET /bars HTTP/1.1" 409 -
DEBUG:root:Engine created!
DEBUG:root:DefaultConnection full
DEBUG:root:Exception when we try fetch Bars: (psycopg2.OperationalError) FATAL:  database "invitame_una_cerveza" does not exist

(Background on this error at: http://sqlalche.me/e/e3q8)"
DEBUG:root:Paso bares
DEBUG:root:Unexpected Error object of type 'NoneType' has no len()
INFO:werkzeug:127.0.0.1 - - [12/Apr/2020 16:23:30] "GET /bars HTTP/1.1" 409 -
DEBUG:root:Engine created!
DEBUG:root:DataBase no exists!
DEBUG:root:Database created!
DEBUG:root:DataDefinitionLanguage created!
INFO:werkzeug:127.0.0.1 - - [12/Apr/2020 16:23:36] "GET /create_data_base HTTP/1.1" 200 -
DEBUG:root:Engine created!
DEBUG:root:Begin insert DML!
DEBUG:root:DefaultConnection full
DEBUG:root:DataModelingLanguage begin!
DEBUG:root:dumps
DEBUG:root:DataModelingLanguage created!
DEBUG:root:DataModelingLanguage created!
INFO:werkzeug:127.0.0.1 - - [12/Apr/2020 16:24:05] "GET /create_database_dml HTTP/1.1" 200 -
INFO:werkzeug:127.0.0.1 - - [12/Apr/2020 16:24:12] "OPTIONS /bars HTTP/1.1" 200 -
DEBUG:urllib3.connectionpool:Starting new HTTP connection (1): api.openweathermap.org:80
DEBUG:urllib3.connectionpool:http://api.openweathermap.org:80 "GET /data/2.5/weather?q=Bogota&units=metric&appid=8cde928e3f9fdc6ce35a4f5d0375ac62 HTTP/1.1" 200 460
INFO:werkzeug:127.0.0.1 - - [12/Apr/2020 16:24:12] "GET /climate/weather/Bogota HTTP/1.1" 200 -
DEBUG:root:Engine created!
DEBUG:root:DefaultConnection full
DEBUG:root:Paso bares
INFO:werkzeug:127.0.0.1 - - [12/Apr/2020 16:24:12] "GET /bars HTTP/1.1" 200 -
DEBUG:urllib3.connectionpool:Starting new HTTP connection (1): api.openweathermap.org:80
DEBUG:urllib3.connectionpool:http://api.openweathermap.org:80 "GET /data/2.5/weather?q=Bogota&units=metric&appid=8cde928e3f9fdc6ce35a4f5d0375ac62 HTTP/1.1" 200 460
INFO:werkzeug:127.0.0.1 - - [12/Apr/2020 16:25:57] "GET /climate/weather/Bogota HTTP/1.1" 200 -
INFO:werkzeug:127.0.0.1 - - [12/Apr/2020 16:26:02] "OPTIONS /bars HTTP/1.1" 200 -
DEBUG:root:Engine created!
DEBUG:root:DefaultConnection full
DEBUG:urllib3.connectionpool:Starting new HTTP connection (1): api.openweathermap.org:80
DEBUG:root:Paso bares
INFO:werkzeug:127.0.0.1 - - [12/Apr/2020 16:26:03] "GET /bars HTTP/1.1" 200 -
DEBUG:urllib3.connectionpool:http://api.openweathermap.org:80 "GET /data/2.5/weather?q=Bogota&units=metric&appid=8cde928e3f9fdc6ce35a4f5d0375ac62 HTTP/1.1" 200 460
INFO:werkzeug:127.0.0.1 - - [12/Apr/2020 16:26:03] "GET /climate/weather/Bogota HTTP/1.1" 200 -
INFO:werkzeug:127.0.0.1 - - [12/Apr/2020 16:26:35] "OPTIONS /bars HTTP/1.1" 200 -
DEBUG:urllib3.connectionpool:Starting new HTTP connection (1): api.openweathermap.org:80
DEBUG:urllib3.connectionpool:http://api.openweathermap.org:80 "GET /data/2.5/weather?q=Bogota&units=metric&appid=8cde928e3f9fdc6ce35a4f5d0375ac62 HTTP/1.1" 200 460
INFO:werkzeug:127.0.0.1 - - [12/Apr/2020 16:26:35] "GET /climate/weather/Bogota HTTP/1.1" 200 -
DEBUG:root:Engine created!
DEBUG:root:DefaultConnection full
DEBUG:root:Paso bares
INFO:werkzeug:127.0.0.1 - - [12/Apr/2020 16:26:35] "GET /bars HTTP/1.1" 200 -
INFO:werkzeug:127.0.0.1 - - [12/Apr/2020 16:26:54] "OPTIONS /bars HTTP/1.1" 200 -
DEBUG:urllib3.connectionpool:Starting new HTTP connection (1): api.openweathermap.org:80
DEBUG:urllib3.connectionpool:http://api.openweathermap.org:80 "GET /data/2.5/weather?q=Bogota&units=metric&appid=8cde928e3f9fdc6ce35a4f5d0375ac62 HTTP/1.1" 200 460
INFO:werkzeug:127.0.0.1 - - [12/Apr/2020 16:26:54] "GET /climate/weather/Bogota HTTP/1.1" 200 -
DEBUG:root:Engine created!
DEBUG:root:DefaultConnection full
DEBUG:root:Paso bares
INFO:werkzeug:127.0.0.1 - - [12/Apr/2020 16:26:55] "GET /bars HTTP/1.1" 200 -
INFO:werkzeug: * Running on http://127.0.0.1:5000/ (Press CTRL+C to quit)
INFO:werkzeug:127.0.0.1 - - [12/Apr/2020 16:29:28] "OPTIONS /bars HTTP/1.1" 200 -
DEBUG:root:Engine created!
DEBUG:root:DefaultConnection full
DEBUG:urllib3.connectionpool:Starting new HTTP connection (1): api.openweathermap.org:80
DEBUG:urllib3.connectionpool:http://api.openweathermap.org:80 "GET /data/2.5/weather?q=Bogota&units=metric&appid=8cde928e3f9fdc6ce35a4f5d0375ac62 HTTP/1.1" 200 460
INFO:werkzeug:127.0.0.1 - - [12/Apr/2020 16:29:29] "GET /climate/weather/Bogota HTTP/1.1" 200 -
DEBUG:root:Paso bares
DEBUG:root:Unexpected Error Object of type Bar is not JSON serializable
INFO:werkzeug:127.0.0.1 - - [12/Apr/2020 16:29:29] "GET /bars HTTP/1.1" 409 -
DEBUG:root:Engine created!
DEBUG:root:DefaultConnection full
DEBUG:root:Paso bares
DEBUG:root:Unexpected Error Object of type Bar is not JSON serializable
INFO:werkzeug:127.0.0.1 - - [12/Apr/2020 16:29:29] "GET /bars HTTP/1.1" 409 -
INFO:werkzeug: * Running on http://127.0.0.1:5000/ (Press CTRL+C to quit)
DEBUG:root:Engine created!
DEBUG:root:DefaultConnection full
DEBUG:root:Paso bares
INFO:werkzeug:127.0.0.1 - - [12/Apr/2020 16:32:03] "GET /bars HTTP/1.1" 200 -
DEBUG:root:Engine created!
DEBUG:root:DefaultConnection full
DEBUG:root:Paso bares
INFO:werkzeug:127.0.0.1 - - [12/Apr/2020 16:32:22] "GET /bars HTTP/1.1" 200 -
DEBUG:root:Engine created!
DEBUG:root:DefaultConnection full
INFO:werkzeug:127.0.0.1 - - [12/Apr/2020 16:33:12] "GET /beers HTTP/1.1" 200 -
INFO:werkzeug: * Running on http://127.0.0.1:5000/ (Press CTRL+C to quit)
DEBUG:root:Engine created!
DEBUG:root:DefaultConnection full
INFO:werkzeug:127.0.0.1 - - [12/Apr/2020 16:49:31] "GET /beers HTTP/1.1" 200 -
INFO:werkzeug: * Running on http://127.0.0.1:5000/ (Press CTRL+C to quit)
DEBUG:root:Engine created!
DEBUG:root:DefaultConnection full
INFO:werkzeug:127.0.0.1 - - [12/Apr/2020 16:50:37] "GET /beers HTTP/1.1" 200 -
INFO:werkzeug:127.0.0.1 - - [12/Apr/2020 17:43:32] "OPTIONS /bars HTTP/1.1" 200 -
DEBUG:root:Engine created!
DEBUG:root:DefaultConnection full
DEBUG:urllib3.connectionpool:Starting new HTTP connection (1): api.openweathermap.org:80
DEBUG:root:Paso bares
INFO:werkzeug:127.0.0.1 - - [12/Apr/2020 17:43:32] "GET /bars HTTP/1.1" 200 -
DEBUG:urllib3.connectionpool:http://api.openweathermap.org:80 "GET /data/2.5/weather?q=Bogota&units=metric&appid=8cde928e3f9fdc6ce35a4f5d0375ac62 HTTP/1.1" 200 477
INFO:werkzeug:127.0.0.1 - - [12/Apr/2020 17:43:33] "GET /climate/weather/Bogota HTTP/1.1" 200 -
INFO:werkzeug:127.0.0.1 - - [12/Apr/2020 18:51:22] "OPTIONS /bars HTTP/1.1" 200 -
DEBUG:urllib3.connectionpool:Starting new HTTP connection (1): api.openweathermap.org:80
DEBUG:root:Engine created!
DEBUG:root:DefaultConnection full
DEBUG:root:Paso bares
INFO:werkzeug:127.0.0.1 - - [12/Apr/2020 18:51:22] "GET /bars HTTP/1.1" 200 -
DEBUG:urllib3.connectionpool:http://api.openweathermap.org:80 "GET /data/2.5/weather?q=Bogota&units=metric&appid=8cde928e3f9fdc6ce35a4f5d0375ac62 HTTP/1.1" 200 458
INFO:werkzeug:127.0.0.1 - - [12/Apr/2020 18:51:22] "GET /climate/weather/Bogota HTTP/1.1" 200 -
INFO:werkzeug: * Running on http://127.0.0.1:5000/ (Press CTRL+C to quit)
DEBUG:urllib3.connectionpool:Starting new HTTP connection (1): api.openweathermap.org:80
DEBUG:urllib3.connectionpool:http://api.openweathermap.org:80 "GET /data/2.5/weather?q=Bogota&units=metric&appid=8cde928e3f9fdc6ce35a4f5d0375ac62 HTTP/1.1" 200 461
INFO:werkzeug:127.0.0.1 - - [14/Apr/2020 13:04:21] "[37mGET /climate/weather/Bogota HTTP/1.1[0m" 200 -
DEBUG:urllib3.connectionpool:Starting new HTTP connection (1): api.openweathermap.org:80
DEBUG:urllib3.connectionpool:http://api.openweathermap.org:80 "GET /data/2.5/weather?q=Bogota&units=metric&appid=8cde928e3f9fdc6ce35a4f5d0375ac62 HTTP/1.1" 200 461
INFO:werkzeug:127.0.0.1 - - [14/Apr/2020 13:08:02] "[37mGET /climate/weather/Bogota HTTP/1.1[0m" 200 -
DEBUG:urllib3.connectionpool:Starting new HTTP connection (1): api.openweathermap.org:80
DEBUG:urllib3.connectionpool:http://api.openweathermap.org:80 "GET /data/2.5/weather?q=Bogota&units=metric&appid=8cde928e3f9fdc6ce35a4f5d0375ac62 HTTP/1.1" 200 461
INFO:werkzeug:127.0.0.1 - - [14/Apr/2020 13:11:28] "[37mGET /climate/weather/Bogota HTTP/1.1[0m" 200 -
DEBUG:urllib3.connectionpool:Starting new HTTP connection (1): api.openweathermap.org:80
DEBUG:urllib3.connectionpool:http://api.openweathermap.org:80 "GET /data/2.5/weather?q=Bogota&units=metric&appid=8cde928e3f9fdc6ce35a4f5d0375ac62 HTTP/1.1" 200 461
INFO:werkzeug:127.0.0.1 - - [14/Apr/2020 13:13:07] "[37mGET /climate/weather/Bogota HTTP/1.1[0m" 200 -
DEBUG:urllib3.connectionpool:Starting new HTTP connection (1): api.openweathermap.org:80
DEBUG:urllib3.connectionpool:http://api.openweathermap.org:80 "GET /data/2.5/weather?q=Bogota&units=metric&appid=8cde928e3f9fdc6ce35a4f5d0375ac62 HTTP/1.1" 200 461
INFO:werkzeug:127.0.0.1 - - [14/Apr/2020 13:13:46] "[37mGET /climate/weather/Bogota HTTP/1.1[0m" 200 -
DEBUG:urllib3.connectionpool:Starting new HTTP connection (1): api.openweathermap.org:80
DEBUG:urllib3.connectionpool:http://api.openweathermap.org:80 "GET /data/2.5/weather?q=Bogota&units=metric&appid=8cde928e3f9fdc6ce35a4f5d0375ac62 HTTP/1.1" 200 461
INFO:werkzeug:127.0.0.1 - - [14/Apr/2020 13:13:57] "[37mGET /climate/weather/Bogota HTTP/1.1[0m" 200 -
DEBUG:urllib3.connectionpool:Starting new HTTP connection (1): api.openweathermap.org:80
DEBUG:urllib3.connectionpool:http://api.openweathermap.org:80 "GET /data/2.5/weather?q=Bogota&units=metric&appid=8cde928e3f9fdc6ce35a4f5d0375ac62 HTTP/1.1" 200 461
INFO:werkzeug:127.0.0.1 - - [14/Apr/2020 13:13:59] "[37mGET /climate/weather/Bogota HTTP/1.1[0m" 200 -
DEBUG:urllib3.connectionpool:Starting new HTTP connection (1): api.openweathermap.org:80
DEBUG:urllib3.connectionpool:http://api.openweathermap.org:80 "GET /data/2.5/weather?q=Bogota&units=metric&appid=8cde928e3f9fdc6ce35a4f5d0375ac62 HTTP/1.1" 200 461
INFO:werkzeug:127.0.0.1 - - [14/Apr/2020 13:14:01] "[37mGET /climate/weather/Bogota HTTP/1.1[0m" 200 -
DEBUG:urllib3.connectionpool:Starting new HTTP connection (1): api.openweathermap.org:80
DEBUG:urllib3.connectionpool:http://api.openweathermap.org:80 "GET /data/2.5/weather?q=Bogota&units=metric&appid=8cde928e3f9fdc6ce35a4f5d0375ac62 HTTP/1.1" 200 461
INFO:werkzeug:127.0.0.1 - - [14/Apr/2020 13:14:07] "[37mGET /climate/weather/Bogota HTTP/1.1[0m" 200 -
INFO:werkzeug:127.0.0.1 - - [14/Apr/2020 13:14:09] "[37mOPTIONS /bars HTTP/1.1[0m" 200 -
DEBUG:urllib3.connectionpool:Starting new HTTP connection (1): api.openweathermap.org:80
DEBUG:root:Engine created!
DEBUG:root:DefaultConnection full
DEBUG:urllib3.connectionpool:http://api.openweathermap.org:80 "GET /data/2.5/weather?q=Bogota&units=metric&appid=8cde928e3f9fdc6ce35a4f5d0375ac62 HTTP/1.1" 200 461
INFO:werkzeug:127.0.0.1 - - [14/Apr/2020 13:14:10] "[37mGET /climate/weather/Bogota HTTP/1.1[0m" 200 -
DEBUG:root:Paso bares
DEBUG:root:Unexpected Error __init__() got an unexpected keyword argument 'encoding'
INFO:werkzeug:127.0.0.1 - - [14/Apr/2020 13:14:10] "[31m[1mGET /bars HTTP/1.1[0m" 409 -
DEBUG:root:Engine created!
DEBUG:root:DefaultConnection full
DEBUG:root:Paso bares
DEBUG:root:Unexpected Error __init__() got an unexpected keyword argument 'encoding'
INFO:werkzeug:127.0.0.1 - - [14/Apr/2020 13:14:10] "[31m[1mGET /bars HTTP/1.1[0m" 409 -
DEBUG:root:Engine created!
DEBUG:root:DefaultConnection full
DEBUG:root:Paso bares
DEBUG:root:Unexpected Error __init__() got an unexpected keyword argument 'encoding'
INFO:werkzeug:127.0.0.1 - - [14/Apr/2020 13:14:32] "[31m[1mGET /bars HTTP/1.1[0m" 409 -
INFO:werkzeug:127.0.0.1 - - [14/Apr/2020 13:14:32] "[33mGET /favicon.ico HTTP/1.1[0m" 404 -
INFO:werkzeug:127.0.0.1 - - [14/Apr/2020 13:15:24] "[37mOPTIONS /bars HTTP/1.1[0m" 200 -
DEBUG:urllib3.connectionpool:Starting new HTTP connection (1): api.openweathermap.org:80
DEBUG:root:Engine created!
DEBUG:root:DefaultConnection full
DEBUG:urllib3.connectionpool:http://api.openweathermap.org:80 "GET /data/2.5/weather?q=Bogota&units=metric&appid=8cde928e3f9fdc6ce35a4f5d0375ac62 HTTP/1.1" 200 461
INFO:werkzeug:127.0.0.1 - - [14/Apr/2020 13:15:24] "[37mGET /climate/weather/Bogota HTTP/1.1[0m" 200 -
DEBUG:root:Paso bares
DEBUG:root:Unexpected Error __init__() got an unexpected keyword argument 'encoding'
INFO:werkzeug:127.0.0.1 - - [14/Apr/2020 13:15:24] "[31m[1mGET /bars HTTP/1.1[0m" 409 -
DEBUG:root:Engine created!
DEBUG:root:DefaultConnection full
DEBUG:root:Paso bares
DEBUG:root:Unexpected Error __init__() got an unexpected keyword argument 'encoding'
INFO:werkzeug:127.0.0.1 - - [14/Apr/2020 13:15:24] "[31m[1mGET /bars HTTP/1.1[0m" 409 -
INFO:werkzeug: * Running on http://127.0.0.1:5000/ (Press CTRL+C to quit)
DEBUG:root:Engine created!
DEBUG:root:DefaultConnection full
DEBUG:root:Unexpected Error __init__() got an unexpected keyword argument 'encoding'
INFO:werkzeug:127.0.0.1 - - [14/Apr/2020 13:17:26] "[31m[1mGET /bars HTTP/1.1[0m" 409 -
INFO:werkzeug: * Running on http://127.0.0.1:5000/ (Press CTRL+C to quit)
DEBUG:root:Engine created!
DEBUG:root:DefaultConnection full
DEBUG:root:Paso bares
DEBUG:root:Unexpected Error Object of type Bar is not JSON serializable
INFO:werkzeug:127.0.0.1 - - [14/Apr/2020 13:20:06] "[31m[1mGET /bars HTTP/1.1[0m" 409 -
INFO:werkzeug: * Running on http://127.0.0.1:5000/ (Press CTRL+C to quit)
DEBUG:root:Engine created!
DEBUG:root:DefaultConnection full
DEBUG:root:Paso bares
DEBUG:root:Unexpected Error Object of type Bar is not JSON serializable
INFO:werkzeug:127.0.0.1 - - [14/Apr/2020 13:20:54] "[31m[1mGET /bars HTTP/1.1[0m" 409 -
INFO:werkzeug: * Running on http://127.0.0.1:5000/ (Press CTRL+C to quit)
DEBUG:root:Engine created!
DEBUG:root:DefaultConnection full
DEBUG:root:Paso bares
DEBUG:root:<Response 2 bytes [200 OK]>
DEBUG:root:Unexpected Error __init__() got an unexpected keyword argument 'encoding'
INFO:werkzeug:127.0.0.1 - - [14/Apr/2020 13:21:35] "[31m[1mGET /bars HTTP/1.1[0m" 409 -
INFO:werkzeug: * Running on http://127.0.0.1:5000/ (Press CTRL+C to quit)
DEBUG:root:Engine created!
DEBUG:root:DefaultConnection full
DEBUG:root:Paso bares
DEBUG:root:1
DEBUG:root:Unexpected Error __init__() got an unexpected keyword argument 'encoding'
INFO:werkzeug:127.0.0.1 - - [14/Apr/2020 13:22:37] "[31m[1mGET /bars HTTP/1.1[0m" 409 -
INFO:werkzeug: * Running on http://127.0.0.1:5000/ (Press CTRL+C to quit)
INFO:werkzeug:127.0.0.1 - - [14/May/2020 12:31:24] "[37mOPTIONS /bars HTTP/1.1[0m" 200 -
DEBUG:urllib3.connectionpool:Starting new HTTP connection (1): api.openweathermap.org:80
DEBUG:root:Engine created!
DEBUG:root:DefaultConnection full
DEBUG:urllib3.connectionpool:http://api.openweathermap.org:80 "GET /data/2.5/weather?q=Bogota&units=metric&appid=8cde928e3f9fdc6ce35a4f5d0375ac62 HTTP/1.1" 200 457
INFO:werkzeug:127.0.0.1 - - [14/May/2020 12:31:24] "[37mGET /climate/weather/Bogota HTTP/1.1[0m" 200 -
DEBUG:root:Exception when we try fetch Bars: (psycopg2.OperationalError) FATAL:  database "invitame_una_cerveza" does not exist

(Background on this error at: http://sqlalche.me/e/e3q8)"
DEBUG:root:Paso bares
DEBUG:root:Unexpected Error object of type 'NoneType' has no len()
INFO:werkzeug:127.0.0.1 - - [14/May/2020 12:31:25] "[31m[1mGET /bars HTTP/1.1[0m" 409 -
DEBUG:root:Engine created!
DEBUG:root:DefaultConnection full
DEBUG:root:Exception when we try fetch Bars: (psycopg2.OperationalError) FATAL:  database "invitame_una_cerveza" does not exist

(Background on this error at: http://sqlalche.me/e/e3q8)"
DEBUG:root:Paso bares
DEBUG:root:Unexpected Error object of type 'NoneType' has no len()
INFO:werkzeug:127.0.0.1 - - [14/May/2020 12:31:25] "[31m[1mGET /bars HTTP/1.1[0m" 409 -
DEBUG:root:Engine created!
DEBUG:root:DataBase no exists!
DEBUG:root:Database created!
DEBUG:root:DataDefinitionLanguage created!
INFO:werkzeug:127.0.0.1 - - [14/May/2020 12:41:34] "[37mGET /create_data_base HTTP/1.1[0m" 200 -
INFO:werkzeug:127.0.0.1 - - [14/May/2020 12:41:34] "[33mGET /favicon.ico HTTP/1.1[0m" 404 -
DEBUG:root:Engine created!
DEBUG:root:Begin insert DML!
DEBUG:root:DefaultConnection full
DEBUG:root:DataModelingLanguage begin!
DEBUG:root:dumps
DEBUG:root:DataModelingLanguage created!
DEBUG:root:DataModelingLanguage created!
INFO:werkzeug:127.0.0.1 - - [14/May/2020 12:41:51] "[37mGET /create_database_dml HTTP/1.1[0m" 200 -
DEBUG:root:Engine created!
DEBUG:root:DefaultConnection full
DEBUG:root:Paso bares
DEBUG:root:1
DEBUG:root:Unexpected Error __init__() got an unexpected keyword argument 'encoding'
INFO:werkzeug:127.0.0.1 - - [14/May/2020 12:42:11] "[31m[1mGET /bars HTTP/1.1[0m" 409 -
INFO:werkzeug: * Running on http://127.0.0.1:5000/ (Press CTRL+C to quit)
DEBUG:root:Engine created!
DEBUG:root:DefaultConnection full
DEBUG:root:Paso bares
DEBUG:root:1
DEBUG:root:Unexpected Error __init__() got an unexpected keyword argument 'encoding'
INFO:werkzeug:127.0.0.1 - - [14/May/2020 12:43:45] "[31m[1mGET /bars HTTP/1.1[0m" 409 -
INFO:werkzeug: * Running on http://127.0.0.1:5000/ (Press CTRL+C to quit)
DEBUG:root:Engine created!
DEBUG:root:DefaultConnection full
DEBUG:root:Exception when we try fetch Bars: serialize() takes 1 positional argument but 2 were given"
DEBUG:root:Paso bares
DEBUG:root:Unexpected Error object of type 'NoneType' has no len()
INFO:werkzeug:127.0.0.1 - - [18/May/2020 12:15:50] "[31m[1mGET /bars HTTP/1.1[0m" 409 -
INFO:werkzeug: * Running on http://127.0.0.1:5000/ (Press CTRL+C to quit)
DEBUG:root:Engine created!
DEBUG:root:DefaultConnection full
DEBUG:root:Paso bares
DEBUG:root:1
INFO:werkzeug:127.0.0.1 - - [18/May/2020 12:22:36] "[37mGET /bars HTTP/1.1[0m" 200 -
INFO:werkzeug: * Running on http://127.0.0.1:5000/ (Press CTRL+C to quit)
DEBUG:root:Engine created!
DEBUG:root:DefaultConnection full
DEBUG:root:Unexpected Error __init__() got an unexpected keyword argument 'encoding'
INFO:werkzeug:127.0.0.1 - - [18/May/2020 12:43:22] "[31m[1mGET /beers HTTP/1.1[0m" 409 -
INFO:werkzeug: * Running on http://127.0.0.1:5000/ (Press CTRL+C to quit)
DEBUG:root:Engine created!
DEBUG:root:DefaultConnection full
INFO:werkzeug:127.0.0.1 - - [18/May/2020 12:44:20] "[37mGET /beers HTTP/1.1[0m" 200 -
DEBUG:urllib3.connectionpool:Starting new HTTP connection (1): api.openweathermap.org:80
DEBUG:urllib3.connectionpool:http://api.openweathermap.org:80 "GET /data/2.5/weather?q=Bogota&units=metric&appid=8cde928e3f9fdc6ce35a4f5d0375ac62 HTTP/1.1" 200 458
INFO:werkzeug:127.0.0.1 - - [18/May/2020 12:50:20] "[37mGET /climate/weather/Bogota HTTP/1.1[0m" 200 -
INFO:werkzeug:127.0.0.1 - - [18/May/2020 12:50:34] "[37mOPTIONS /bars HTTP/1.1[0m" 200 -
DEBUG:urllib3.connectionpool:Starting new HTTP connection (1): api.openweathermap.org:80
DEBUG:urllib3.connectionpool:http://api.openweathermap.org:80 "GET /data/2.5/weather?q=Bogota&units=metric&appid=8cde928e3f9fdc6ce35a4f5d0375ac62 HTTP/1.1" 200 458
INFO:werkzeug:127.0.0.1 - - [18/May/2020 12:50:34] "[37mGET /climate/weather/Bogota HTTP/1.1[0m" 200 -
DEBUG:root:Engine created!
DEBUG:root:DefaultConnection full
INFO:werkzeug:127.0.0.1 - - [18/May/2020 12:50:34] "[37mGET /bars HTTP/1.1[0m" 200 -
INFO:werkzeug:127.0.0.1 - - [18/May/2020 12:51:01] "[37mOPTIONS /bars HTTP/1.1[0m" 200 -
DEBUG:urllib3.connectionpool:Starting new HTTP connection (1): api.openweathermap.org:80
DEBUG:urllib3.connectionpool:http://api.openweathermap.org:80 "GET /data/2.5/weather?q=Bogota&units=metric&appid=8cde928e3f9fdc6ce35a4f5d0375ac62 HTTP/1.1" 200 458
INFO:werkzeug:127.0.0.1 - - [18/May/2020 12:51:01] "[37mGET /climate/weather/Bogota HTTP/1.1[0m" 200 -
DEBUG:root:Engine created!
DEBUG:root:DefaultConnection full
INFO:werkzeug:127.0.0.1 - - [18/May/2020 12:51:02] "[37mGET /bars HTTP/1.1[0m" 200 -
INFO:werkzeug:127.0.0.1 - - [18/May/2020 12:52:04] "[37mOPTIONS /bars HTTP/1.1[0m" 200 -
DEBUG:urllib3.connectionpool:Starting new HTTP connection (1): api.openweathermap.org:80
DEBUG:root:Engine created!
DEBUG:root:DefaultConnection full
DEBUG:urllib3.connectionpool:http://api.openweathermap.org:80 "GET /data/2.5/weather?q=Bogota&units=metric&appid=8cde928e3f9fdc6ce35a4f5d0375ac62 HTTP/1.1" 200 458
INFO:werkzeug:127.0.0.1 - - [18/May/2020 12:52:05] "[37mGET /climate/weather/Bogota HTTP/1.1[0m" 200 -
INFO:werkzeug:127.0.0.1 - - [18/May/2020 12:52:05] "[37mGET /bars HTTP/1.1[0m" 200 -
DEBUG:urllib3.connectionpool:Starting new HTTP connection (1): api.openweathermap.org:80
DEBUG:urllib3.connectionpool:http://api.openweathermap.org:80 "GET /data/2.5/weather?q=Bogota&units=metric&appid=8cde928e3f9fdc6ce35a4f5d0375ac62 HTTP/1.1" 200 458
INFO:werkzeug:127.0.0.1 - - [18/May/2020 12:52:05] "[37mGET /climate/weather/Bogota HTTP/1.1[0m" 200 -
DEBUG:urllib3.connectionpool:Starting new HTTP connection (1): api.openweathermap.org:80
DEBUG:urllib3.connectionpool:http://api.openweathermap.org:80 "GET /data/2.5/weather?q=Bogota&units=metric&appid=8cde928e3f9fdc6ce35a4f5d0375ac62 HTTP/1.1" 200 458
INFO:werkzeug:127.0.0.1 - - [18/May/2020 12:52:35] "[37mGET /climate/weather/Bogota HTTP/1.1[0m" 200 -
INFO:werkzeug:127.0.0.1 - - [18/May/2020 12:52:50] "[37mOPTIONS /bars HTTP/1.1[0m" 200 -
DEBUG:urllib3.connectionpool:Starting new HTTP connection (1): api.openweathermap.org:80
DEBUG:urllib3.connectionpool:http://api.openweathermap.org:80 "GET /data/2.5/weather?q=Bogota&units=metric&appid=8cde928e3f9fdc6ce35a4f5d0375ac62 HTTP/1.1" 200 458
INFO:werkzeug:127.0.0.1 - - [18/May/2020 12:52:50] "[37mGET /climate/weather/Bogota HTTP/1.1[0m" 200 -
DEBUG:root:Engine created!
DEBUG:root:DefaultConnection full
INFO:werkzeug:127.0.0.1 - - [18/May/2020 12:52:50] "[37mGET /bars HTTP/1.1[0m" 200 -
INFO:werkzeug:127.0.0.1 - - [18/May/2020 12:53:38] "[37mOPTIONS /beer/Melas/GET HTTP/1.1[0m" 200 -
DEBUG:urllib3.connectionpool:Starting new HTTP connection (1): api.openweathermap.org:80
DEBUG:root:Engine created!
DEBUG:root:DefaultConnection full
DEBUG:urllib3.connectionpool:http://api.openweathermap.org:80 "GET /data/2.5/weather?q=Bogota&units=metric&appid=8cde928e3f9fdc6ce35a4f5d0375ac62 HTTP/1.1" 200 458
INFO:werkzeug:127.0.0.1 - - [18/May/2020 12:53:39] "[37mGET /climate/weather/Bogota HTTP/1.1[0m" 200 -
DEBUG:root:Unexpected Error (psycopg2.errors.InvalidTextRepresentation) invalid input syntax for type integer: "Melas"
LINE 3: WHERE public."BEER".id = 'Melas'
                                 ^

[SQL: SELECT public."BEER".created_at AS "public_BEER_created_at", public."BEER".updated_at AS "public_BEER_updated_at", public."BEER".last_updated_by AS "public_BEER_last_updated_by", public."BEER".id AS "public_BEER_id", public."BEER".name AS "public_BEER_name", public."BEER".pint_price AS "public_BEER_pint_price", public."BEER".cup330_price AS "public_BEER_cup330_price", public."BEER".giraffe_price AS "public_BEER_giraffe_price", public."BEER".pitcher_price AS "public_BEER_pitcher_price", public."BEER".bar_id AS "public_BEER_bar_id", public."BEER".beer_type_id AS "public_BEER_beer_type_id", public."BEER".avb AS "public_BEER_avb", public."BEER".ibu AS "public_BEER_ibu", public."BEER".srm AS "public_BEER_srm", public."BEER".description AS "public_BEER_description", public."BEER".image AS "public_BEER_image", public."BEER".pint AS "public_BEER_pint", public."BEER".cup330 AS "public_BEER_cup330", public."BEER".giraffe AS "public_BEER_giraffe", public."BEER".pitcher AS "public_BEER_pitcher" 
FROM public."BEER" 
WHERE public."BEER".id = %(id_1)s]
[parameters: {'id_1': 'Melas'}]
(Background on this error at: http://sqlalche.me/e/9h9h)
INFO:werkzeug:127.0.0.1 - - [18/May/2020 12:53:39] "[31m[1mGET /beer/Melas/GET HTTP/1.1[0m" 409 -
DEBUG:root:Engine created!
DEBUG:root:DefaultConnection full
DEBUG:root:Unexpected Error (psycopg2.errors.InvalidTextRepresentation) invalid input syntax for type integer: "Melas"
LINE 3: WHERE public."BEER".id = 'Melas'
                                 ^

[SQL: SELECT public."BEER".created_at AS "public_BEER_created_at", public."BEER".updated_at AS "public_BEER_updated_at", public."BEER".last_updated_by AS "public_BEER_last_updated_by", public."BEER".id AS "public_BEER_id", public."BEER".name AS "public_BEER_name", public."BEER".pint_price AS "public_BEER_pint_price", public."BEER".cup330_price AS "public_BEER_cup330_price", public."BEER".giraffe_price AS "public_BEER_giraffe_price", public."BEER".pitcher_price AS "public_BEER_pitcher_price", public."BEER".bar_id AS "public_BEER_bar_id", public."BEER".beer_type_id AS "public_BEER_beer_type_id", public."BEER".avb AS "public_BEER_avb", public."BEER".ibu AS "public_BEER_ibu", public."BEER".srm AS "public_BEER_srm", public."BEER".description AS "public_BEER_description", public."BEER".image AS "public_BEER_image", public."BEER".pint AS "public_BEER_pint", public."BEER".cup330 AS "public_BEER_cup330", public."BEER".giraffe AS "public_BEER_giraffe", public."BEER".pitcher AS "public_BEER_pitcher" 
FROM public."BEER" 
WHERE public."BEER".id = %(id_1)s]
[parameters: {'id_1': 'Melas'}]
(Background on this error at: http://sqlalche.me/e/9h9h)
INFO:werkzeug:127.0.0.1 - - [18/May/2020 12:53:39] "[31m[1mGET /beer/Melas/GET HTTP/1.1[0m" 409 -
INFO:werkzeug:127.0.0.1 - - [18/May/2020 12:56:41] "[37mOPTIONS /beer/Melas/GET HTTP/1.1[0m" 200 -
DEBUG:urllib3.connectionpool:Starting new HTTP connection (1): api.openweathermap.org:80
DEBUG:root:Engine created!
DEBUG:root:DefaultConnection full
DEBUG:root:Unexpected Error (psycopg2.errors.InvalidTextRepresentation) invalid input syntax for type integer: "Melas"
LINE 3: WHERE public."BEER".id = 'Melas'
                                 ^

[SQL: SELECT public."BEER".created_at AS "public_BEER_created_at", public."BEER".updated_at AS "public_BEER_updated_at", public."BEER".last_updated_by AS "public_BEER_last_updated_by", public."BEER".id AS "public_BEER_id", public."BEER".name AS "public_BEER_name", public."BEER".pint_price AS "public_BEER_pint_price", public."BEER".cup330_price AS "public_BEER_cup330_price", public."BEER".giraffe_price AS "public_BEER_giraffe_price", public."BEER".pitcher_price AS "public_BEER_pitcher_price", public."BEER".bar_id AS "public_BEER_bar_id", public."BEER".beer_type_id AS "public_BEER_beer_type_id", public."BEER".avb AS "public_BEER_avb", public."BEER".ibu AS "public_BEER_ibu", public."BEER".srm AS "public_BEER_srm", public."BEER".description AS "public_BEER_description", public."BEER".image AS "public_BEER_image", public."BEER".pint AS "public_BEER_pint", public."BEER".cup330 AS "public_BEER_cup330", public."BEER".giraffe AS "public_BEER_giraffe", public."BEER".pitcher AS "public_BEER_pitcher" 
FROM public."BEER" 
WHERE public."BEER".id = %(id_1)s]
[parameters: {'id_1': 'Melas'}]
(Background on this error at: http://sqlalche.me/e/9h9h)
INFO:werkzeug:127.0.0.1 - - [18/May/2020 12:56:42] "[31m[1mGET /beer/Melas/GET HTTP/1.1[0m" 409 -
DEBUG:root:Engine created!
DEBUG:root:DefaultConnection full
DEBUG:root:Unexpected Error (psycopg2.errors.InvalidTextRepresentation) invalid input syntax for type integer: "Melas"
LINE 3: WHERE public."BEER".id = 'Melas'
                                 ^

[SQL: SELECT public."BEER".created_at AS "public_BEER_created_at", public."BEER".updated_at AS "public_BEER_updated_at", public."BEER".last_updated_by AS "public_BEER_last_updated_by", public."BEER".id AS "public_BEER_id", public."BEER".name AS "public_BEER_name", public."BEER".pint_price AS "public_BEER_pint_price", public."BEER".cup330_price AS "public_BEER_cup330_price", public."BEER".giraffe_price AS "public_BEER_giraffe_price", public."BEER".pitcher_price AS "public_BEER_pitcher_price", public."BEER".bar_id AS "public_BEER_bar_id", public."BEER".beer_type_id AS "public_BEER_beer_type_id", public."BEER".avb AS "public_BEER_avb", public."BEER".ibu AS "public_BEER_ibu", public."BEER".srm AS "public_BEER_srm", public."BEER".description AS "public_BEER_description", public."BEER".image AS "public_BEER_image", public."BEER".pint AS "public_BEER_pint", public."BEER".cup330 AS "public_BEER_cup330", public."BEER".giraffe AS "public_BEER_giraffe", public."BEER".pitcher AS "public_BEER_pitcher" 
FROM public."BEER" 
WHERE public."BEER".id = %(id_1)s]
[parameters: {'id_1': 'Melas'}]
(Background on this error at: http://sqlalche.me/e/9h9h)
INFO:werkzeug:127.0.0.1 - - [18/May/2020 12:56:42] "[31m[1mGET /beer/Melas/GET HTTP/1.1[0m" 409 -
DEBUG:urllib3.connectionpool:http://api.openweathermap.org:80 "GET /data/2.5/weather?q=Bogota&units=metric&appid=8cde928e3f9fdc6ce35a4f5d0375ac62 HTTP/1.1" 200 458
INFO:werkzeug:127.0.0.1 - - [18/May/2020 12:56:42] "[37mGET /climate/weather/Bogota HTTP/1.1[0m" 200 -
INFO:werkzeug:127.0.0.1 - - [18/May/2020 12:56:53] "[37mOPTIONS /beer/Melas/GET HTTP/1.1[0m" 200 -
DEBUG:urllib3.connectionpool:Starting new HTTP connection (1): api.openweathermap.org:80
DEBUG:root:Engine created!
DEBUG:root:DefaultConnection full
DEBUG:root:Unexpected Error (psycopg2.errors.InvalidTextRepresentation) invalid input syntax for type integer: "Melas"
LINE 3: WHERE public."BEER".id = 'Melas'
                                 ^

[SQL: SELECT public."BEER".created_at AS "public_BEER_created_at", public."BEER".updated_at AS "public_BEER_updated_at", public."BEER".last_updated_by AS "public_BEER_last_updated_by", public."BEER".id AS "public_BEER_id", public."BEER".name AS "public_BEER_name", public."BEER".pint_price AS "public_BEER_pint_price", public."BEER".cup330_price AS "public_BEER_cup330_price", public."BEER".giraffe_price AS "public_BEER_giraffe_price", public."BEER".pitcher_price AS "public_BEER_pitcher_price", public."BEER".bar_id AS "public_BEER_bar_id", public."BEER".beer_type_id AS "public_BEER_beer_type_id", public."BEER".avb AS "public_BEER_avb", public."BEER".ibu AS "public_BEER_ibu", public."BEER".srm AS "public_BEER_srm", public."BEER".description AS "public_BEER_description", public."BEER".image AS "public_BEER_image", public."BEER".pint AS "public_BEER_pint", public."BEER".cup330 AS "public_BEER_cup330", public."BEER".giraffe AS "public_BEER_giraffe", public."BEER".pitcher AS "public_BEER_pitcher" 
FROM public."BEER" 
WHERE public."BEER".id = %(id_1)s]
[parameters: {'id_1': 'Melas'}]
(Background on this error at: http://sqlalche.me/e/9h9h)
INFO:werkzeug:127.0.0.1 - - [18/May/2020 12:56:53] "[31m[1mGET /beer/Melas/GET HTTP/1.1[0m" 409 -
DEBUG:root:Engine created!
DEBUG:root:DefaultConnection full
DEBUG:urllib3.connectionpool:http://api.openweathermap.org:80 "GET /data/2.5/weather?q=Bogota&units=metric&appid=8cde928e3f9fdc6ce35a4f5d0375ac62 HTTP/1.1" 200 458
INFO:werkzeug:127.0.0.1 - - [18/May/2020 12:56:53] "[37mGET /climate/weather/Bogota HTTP/1.1[0m" 200 -
DEBUG:root:Unexpected Error (psycopg2.errors.InvalidTextRepresentation) invalid input syntax for type integer: "Melas"
LINE 3: WHERE public."BEER".id = 'Melas'
                                 ^

[SQL: SELECT public."BEER".created_at AS "public_BEER_created_at", public."BEER".updated_at AS "public_BEER_updated_at", public."BEER".last_updated_by AS "public_BEER_last_updated_by", public."BEER".id AS "public_BEER_id", public."BEER".name AS "public_BEER_name", public."BEER".pint_price AS "public_BEER_pint_price", public."BEER".cup330_price AS "public_BEER_cup330_price", public."BEER".giraffe_price AS "public_BEER_giraffe_price", public."BEER".pitcher_price AS "public_BEER_pitcher_price", public."BEER".bar_id AS "public_BEER_bar_id", public."BEER".beer_type_id AS "public_BEER_beer_type_id", public."BEER".avb AS "public_BEER_avb", public."BEER".ibu AS "public_BEER_ibu", public."BEER".srm AS "public_BEER_srm", public."BEER".description AS "public_BEER_description", public."BEER".image AS "public_BEER_image", public."BEER".pint AS "public_BEER_pint", public."BEER".cup330 AS "public_BEER_cup330", public."BEER".giraffe AS "public_BEER_giraffe", public."BEER".pitcher AS "public_BEER_pitcher" 
FROM public."BEER" 
WHERE public."BEER".id = %(id_1)s]
[parameters: {'id_1': 'Melas'}]
(Background on this error at: http://sqlalche.me/e/9h9h)
INFO:werkzeug:127.0.0.1 - - [18/May/2020 12:56:53] "[31m[1mGET /beer/Melas/GET HTTP/1.1[0m" 409 -
INFO:werkzeug:127.0.0.1 - - [18/May/2020 12:56:57] "[37mOPTIONS /bars HTTP/1.1[0m" 200 -
DEBUG:urllib3.connectionpool:Starting new HTTP connection (1): api.openweathermap.org:80
DEBUG:root:Engine created!
DEBUG:root:DefaultConnection full
INFO:werkzeug:127.0.0.1 - - [18/May/2020 12:56:57] "[37mGET /bars HTTP/1.1[0m" 200 -
DEBUG:urllib3.connectionpool:http://api.openweathermap.org:80 "GET /data/2.5/weather?q=Bogota&units=metric&appid=8cde928e3f9fdc6ce35a4f5d0375ac62 HTTP/1.1" 200 458
INFO:werkzeug:127.0.0.1 - - [18/May/2020 12:56:57] "[37mGET /climate/weather/Bogota HTTP/1.1[0m" 200 -
INFO:werkzeug:127.0.0.1 - - [18/May/2020 12:57:00] "[37mOPTIONS /beer/1/GET HTTP/1.1[0m" 200 -
DEBUG:root:Engine created!
DEBUG:root:DefaultConnection full
DEBUG:urllib3.connectionpool:Starting new HTTP connection (1): api.openweathermap.org:80
DEBUG:root:Unexpected Error __init__() got an unexpected keyword argument 'encoding'
INFO:werkzeug:127.0.0.1 - - [18/May/2020 12:57:00] "[31m[1mGET /beer/1/GET HTTP/1.1[0m" 409 -
DEBUG:urllib3.connectionpool:http://api.openweathermap.org:80 "GET /data/2.5/weather?q=Bogota&units=metric&appid=8cde928e3f9fdc6ce35a4f5d0375ac62 HTTP/1.1" 200 458
INFO:werkzeug:127.0.0.1 - - [18/May/2020 12:57:00] "[37mGET /climate/weather/Bogota HTTP/1.1[0m" 200 -
DEBUG:root:Engine created!
DEBUG:root:DefaultConnection full
DEBUG:root:Unexpected Error __init__() got an unexpected keyword argument 'encoding'
INFO:werkzeug:127.0.0.1 - - [18/May/2020 12:57:00] "[31m[1mGET /beer/1/GET HTTP/1.1[0m" 409 -
INFO:werkzeug: * Running on http://127.0.0.1:5000/ (Press CTRL+C to quit)
INFO:werkzeug:127.0.0.1 - - [18/May/2020 13:14:02] "[37mOPTIONS /beer/1/GET HTTP/1.1[0m" 200 -
DEBUG:urllib3.connectionpool:Starting new HTTP connection (1): api.openweathermap.org:80
DEBUG:root:Engine created!
DEBUG:root:DefaultConnection full
DEBUG:urllib3.connectionpool:http://api.openweathermap.org:80 "GET /data/2.5/weather?q=Bogota&units=metric&appid=8cde928e3f9fdc6ce35a4f5d0375ac62 HTTP/1.1" 200 458
INFO:werkzeug:127.0.0.1 - - [18/May/2020 13:14:02] "[37mGET /climate/weather/Bogota HTTP/1.1[0m" 200 -
DEBUG:root:Unexpected Error Object of type Beer is not JSON serializable
INFO:werkzeug:127.0.0.1 - - [18/May/2020 13:14:02] "[31m[1mGET /beer/1/GET HTTP/1.1[0m" 409 -
DEBUG:root:Engine created!
DEBUG:root:DefaultConnection full
DEBUG:root:Unexpected Error Object of type Beer is not JSON serializable
INFO:werkzeug:127.0.0.1 - - [18/May/2020 13:14:02] "[31m[1mGET /beer/1/GET HTTP/1.1[0m" 409 -
DEBUG:urllib3.connectionpool:Starting new HTTP connection (1): api.openweathermap.org:80
DEBUG:urllib3.connectionpool:http://api.openweathermap.org:80 "GET /data/2.5/weather?q=Bogota&units=metric&appid=8cde928e3f9fdc6ce35a4f5d0375ac62 HTTP/1.1" 200 458
INFO:werkzeug:127.0.0.1 - - [18/May/2020 13:17:03] "[37mGET /climate/weather/Bogota HTTP/1.1[0m" 200 -
INFO:werkzeug:127.0.0.1 - - [18/May/2020 13:17:07] "[37mOPTIONS /bars HTTP/1.1[0m" 200 -
DEBUG:urllib3.connectionpool:Starting new HTTP connection (1): api.openweathermap.org:80
DEBUG:root:Engine created!
DEBUG:root:DefaultConnection full
DEBUG:urllib3.connectionpool:http://api.openweathermap.org:80 "GET /data/2.5/weather?q=Bogota&units=metric&appid=8cde928e3f9fdc6ce35a4f5d0375ac62 HTTP/1.1" 200 458
INFO:werkzeug:127.0.0.1 - - [18/May/2020 13:17:08] "[37mGET /climate/weather/Bogota HTTP/1.1[0m" 200 -
INFO:werkzeug:127.0.0.1 - - [18/May/2020 13:17:09] "[37mGET /bars HTTP/1.1[0m" 200 -
INFO:werkzeug:127.0.0.1 - - [18/May/2020 13:17:14] "[37mOPTIONS /beer/1/GET HTTP/1.1[0m" 200 -
DEBUG:urllib3.connectionpool:Starting new HTTP connection (1): api.openweathermap.org:80
DEBUG:root:Engine created!
DEBUG:root:DefaultConnection full
DEBUG:root:Unexpected Error Object of type Beer is not JSON serializable
INFO:werkzeug:127.0.0.1 - - [18/May/2020 13:17:14] "[31m[1mGET /beer/1/GET HTTP/1.1[0m" 409 -
DEBUG:root:Engine created!
DEBUG:root:DefaultConnection full
DEBUG:urllib3.connectionpool:http://api.openweathermap.org:80 "GET /data/2.5/weather?q=Bogota&units=metric&appid=8cde928e3f9fdc6ce35a4f5d0375ac62 HTTP/1.1" 200 458
INFO:werkzeug:127.0.0.1 - - [18/May/2020 13:17:14] "[37mGET /climate/weather/Bogota HTTP/1.1[0m" 200 -
DEBUG:root:Unexpected Error Object of type Beer is not JSON serializable
INFO:werkzeug:127.0.0.1 - - [18/May/2020 13:17:14] "[31m[1mGET /beer/1/GET HTTP/1.1[0m" 409 -
INFO:werkzeug:127.0.0.1 - - [18/May/2020 13:17:56] "[37mOPTIONS /beer/1/GET HTTP/1.1[0m" 200 -
DEBUG:urllib3.connectionpool:Starting new HTTP connection (1): api.openweathermap.org:80
DEBUG:root:Engine created!
DEBUG:root:DefaultConnection full
DEBUG:root:Unexpected Error Object of type Beer is not JSON serializable
INFO:werkzeug:127.0.0.1 - - [18/May/2020 13:17:57] "[31m[1mGET /beer/1/GET HTTP/1.1[0m" 409 -
DEBUG:root:Engine created!
DEBUG:root:DefaultConnection full
DEBUG:root:Unexpected Error Object of type Beer is not JSON serializable
INFO:werkzeug:127.0.0.1 - - [18/May/2020 13:17:57] "[31m[1mGET /beer/1/GET HTTP/1.1[0m" 409 -
DEBUG:urllib3.connectionpool:http://api.openweathermap.org:80 "GET /data/2.5/weather?q=Bogota&units=metric&appid=8cde928e3f9fdc6ce35a4f5d0375ac62 HTTP/1.1" 200 458
INFO:werkzeug:127.0.0.1 - - [18/May/2020 13:17:57] "[37mGET /climate/weather/Bogota HTTP/1.1[0m" 200 -
DEBUG:root:Engine created!
DEBUG:root:DefaultConnection full
DEBUG:root:Unexpected Error Object of type Beer is not JSON serializable
INFO:werkzeug:127.0.0.1 - - [18/May/2020 13:23:18] "[31m[1mGET /beer/1/GET HTTP/1.1[0m" 409 -
INFO:werkzeug: * Running on http://127.0.0.1:5000/ (Press CTRL+C to quit)
DEBUG:root:Engine created!
DEBUG:root:DefaultConnection full
INFO:werkzeug:127.0.0.1 - - [18/May/2020 13:24:52] "[37mGET /beer/1/GET HTTP/1.1[0m" 200 -
INFO:werkzeug:127.0.0.1 - - [18/May/2020 13:25:10] "[37mOPTIONS /beer/1/GET HTTP/1.1[0m" 200 -
DEBUG:urllib3.connectionpool:Starting new HTTP connection (1): api.openweathermap.org:80
DEBUG:root:Engine created!
DEBUG:root:DefaultConnection full
DEBUG:urllib3.connectionpool:http://api.openweathermap.org:80 "GET /data/2.5/weather?q=Bogota&units=metric&appid=8cde928e3f9fdc6ce35a4f5d0375ac62 HTTP/1.1" 200 458
INFO:werkzeug:127.0.0.1 - - [18/May/2020 13:25:10] "[37mGET /climate/weather/Bogota HTTP/1.1[0m" 200 -
INFO:werkzeug:127.0.0.1 - - [18/May/2020 13:25:10] "[37mGET /beer/1/GET HTTP/1.1[0m" 200 -
INFO:werkzeug: * Running on http://127.0.0.1:5000/ (Press CTRL+C to quit)
DEBUG:root:Engine created!
DEBUG:root:DefaultConnection full
DEBUG:root:Unexpected Error 'Beer' object is not iterable
INFO:werkzeug:127.0.0.1 - - [18/May/2020 13:26:14] "[31m[1mGET /beer/1/GET HTTP/1.1[0m" 409 -
INFO:werkzeug:127.0.0.1 - - [18/May/2020 13:38:41] "[37mOPTIONS /beer/1/GET HTTP/1.1[0m" 200 -
DEBUG:urllib3.connectionpool:Starting new HTTP connection (1): api.openweathermap.org:80
DEBUG:root:Engine created!
DEBUG:root:DefaultConnection full
DEBUG:urllib3.connectionpool:http://api.openweathermap.org:80 "GET /data/2.5/weather?q=Bogota&units=metric&appid=8cde928e3f9fdc6ce35a4f5d0375ac62 HTTP/1.1" 200 458
INFO:werkzeug:127.0.0.1 - - [18/May/2020 13:38:41] "[37mGET /climate/weather/Bogota HTTP/1.1[0m" 200 -
DEBUG:root:Unexpected Error 'Beer' object is not iterable
INFO:werkzeug:127.0.0.1 - - [18/May/2020 13:38:41] "[31m[1mGET /beer/1/GET HTTP/1.1[0m" 409 -
DEBUG:root:Engine created!
DEBUG:root:DefaultConnection full
DEBUG:root:Unexpected Error 'Beer' object is not iterable
INFO:werkzeug:127.0.0.1 - - [18/May/2020 13:38:41] "[31m[1mGET /beer/1/GET HTTP/1.1[0m" 409 -
INFO:werkzeug:127.0.0.1 - - [18/May/2020 13:39:48] "[37mOPTIONS /beer/1/GET HTTP/1.1[0m" 200 -
DEBUG:urllib3.connectionpool:Starting new HTTP connection (1): api.openweathermap.org:80
DEBUG:root:Engine created!
DEBUG:root:DefaultConnection full
DEBUG:urllib3.connectionpool:http://api.openweathermap.org:80 "GET /data/2.5/weather?q=Bogota&units=metric&appid=8cde928e3f9fdc6ce35a4f5d0375ac62 HTTP/1.1" 200 458
INFO:werkzeug:127.0.0.1 - - [18/May/2020 13:39:49] "[37mGET /climate/weather/Bogota HTTP/1.1[0m" 200 -
DEBUG:root:Unexpected Error 'Beer' object is not iterable
INFO:werkzeug:127.0.0.1 - - [18/May/2020 13:39:49] "[31m[1mGET /beer/1/GET HTTP/1.1[0m" 409 -
DEBUG:root:Engine created!
DEBUG:root:DefaultConnection full
DEBUG:root:Unexpected Error 'Beer' object is not iterable
INFO:werkzeug:127.0.0.1 - - [18/May/2020 13:39:49] "[31m[1mGET /beer/1/GET HTTP/1.1[0m" 409 -
INFO:werkzeug: * Running on http://127.0.0.1:5000/ (Press CTRL+C to quit)
INFO:werkzeug:127.0.0.1 - - [18/May/2020 13:41:15] "[33mOPTIONS /beers1 HTTP/1.1[0m" 404 -
DEBUG:urllib3.connectionpool:Starting new HTTP connection (1): api.openweathermap.org:80
INFO:werkzeug:127.0.0.1 - - [18/May/2020 13:41:15] "[33mOPTIONS /beers1 HTTP/1.1[0m" 404 -
DEBUG:urllib3.connectionpool:http://api.openweathermap.org:80 "GET /data/2.5/weather?q=Bogota&units=metric&appid=8cde928e3f9fdc6ce35a4f5d0375ac62 HTTP/1.1" 200 458
INFO:werkzeug:127.0.0.1 - - [18/May/2020 13:41:15] "[37mGET /climate/weather/Bogota HTTP/1.1[0m" 200 -
DEBUG:root:Engine created!
DEBUG:root:DefaultConnection full
DEBUG:root:Unexpected Error 'list' object has no attribute 'id'
INFO:werkzeug:127.0.0.1 - - [18/May/2020 13:41:32] "[31m[1mGET /beer/1 HTTP/1.1[0m" 409 -
INFO:werkzeug: * Running on http://127.0.0.1:5000/ (Press CTRL+C to quit)
DEBUG:root:Engine created!
DEBUG:root:DefaultConnection full
INFO:werkzeug:127.0.0.1 - - [18/May/2020 13:42:52] "[37mGET /beer/1 HTTP/1.1[0m" 200 -
INFO:werkzeug:127.0.0.1 - - [18/May/2020 13:43:06] "[33mOPTIONS /beers1 HTTP/1.1[0m" 404 -
DEBUG:urllib3.connectionpool:Starting new HTTP connection (1): api.openweathermap.org:80
INFO:werkzeug:127.0.0.1 - - [18/May/2020 13:43:06] "[33mOPTIONS /beers1 HTTP/1.1[0m" 404 -
DEBUG:urllib3.connectionpool:http://api.openweathermap.org:80 "GET /data/2.5/weather?q=Bogota&units=metric&appid=8cde928e3f9fdc6ce35a4f5d0375ac62 HTTP/1.1" 200 458
INFO:werkzeug:127.0.0.1 - - [18/May/2020 13:43:06] "[37mGET /climate/weather/Bogota HTTP/1.1[0m" 200 -
INFO:werkzeug:127.0.0.1 - - [18/May/2020 13:43:52] "[37mOPTIONS /beer/1 HTTP/1.1[0m" 200 -
DEBUG:urllib3.connectionpool:Starting new HTTP connection (1): api.openweathermap.org:80
DEBUG:urllib3.connectionpool:http://api.openweathermap.org:80 "GET /data/2.5/weather?q=Bogota&units=metric&appid=8cde928e3f9fdc6ce35a4f5d0375ac62 HTTP/1.1" 200 458
INFO:werkzeug:127.0.0.1 - - [18/May/2020 13:43:52] "[37mGET /climate/weather/Bogota HTTP/1.1[0m" 200 -
DEBUG:root:Engine created!
DEBUG:root:DefaultConnection full
INFO:werkzeug:127.0.0.1 - - [18/May/2020 13:43:52] "[37mGET /beer/1 HTTP/1.1[0m" 200 -
INFO:werkzeug:127.0.0.1 - - [18/May/2020 14:55:24] "[37mOPTIONS /beer/1 HTTP/1.1[0m" 200 -
DEBUG:urllib3.connectionpool:Starting new HTTP connection (1): api.openweathermap.org:80
DEBUG:root:Engine created!
DEBUG:root:DefaultConnection full
INFO:werkzeug:127.0.0.1 - - [18/May/2020 14:55:24] "[37mGET /beer/1 HTTP/1.1[0m" 200 -
DEBUG:urllib3.connectionpool:http://api.openweathermap.org:80 "GET /data/2.5/weather?q=Bogota&units=metric&appid=8cde928e3f9fdc6ce35a4f5d0375ac62 HTTP/1.1" 200 458
INFO:werkzeug:127.0.0.1 - - [18/May/2020 14:55:24] "[37mGET /climate/weather/Bogota HTTP/1.1[0m" 200 -
INFO:werkzeug: * Running on http://127.0.0.1:5000/ (Press CTRL+C to quit)
DEBUG:root:Engine created!
DEBUG:root:Database no exists. we going to create it!
INFO:werkzeug:127.0.0.1 - - [18/May/2020 17:45:27] "[31m[1mGET /create_database_dml HTTP/1.1[0m" 409 -
INFO:werkzeug: * Running on http://127.0.0.1:5000/ (Press CTRL+C to quit)
DEBUG:root:Engine created!
DEBUG:root:Database no exists. we going to create it!
ERROR:servicio:Exception on /create_database_dml [GET]
Traceback (most recent call last):
  File "C:\Users\alejo\AppData\Local\Programs\Python\Python38-32\lib\site-packages\sqlalchemy\engine\base.py", line 2275, in _wrap_pool_connect
    return fn()
  File "C:\Users\alejo\AppData\Local\Programs\Python\Python38-32\lib\site-packages\sqlalchemy\pool\base.py", line 363, in connect
    return _ConnectionFairy._checkout(self)
  File "C:\Users\alejo\AppData\Local\Programs\Python\Python38-32\lib\site-packages\sqlalchemy\pool\base.py", line 760, in _checkout
    fairy = _ConnectionRecord.checkout(pool)
  File "C:\Users\alejo\AppData\Local\Programs\Python\Python38-32\lib\site-packages\sqlalchemy\pool\base.py", line 492, in checkout
    rec = pool._do_get()
  File "C:\Users\alejo\AppData\Local\Programs\Python\Python38-32\lib\site-packages\sqlalchemy\pool\impl.py", line 139, in _do_get
    self._dec_overflow()
  File "C:\Users\alejo\AppData\Local\Programs\Python\Python38-32\lib\site-packages\sqlalchemy\util\langhelpers.py", line 68, in __exit__
    compat.reraise(exc_type, exc_value, exc_tb)
  File "C:\Users\alejo\AppData\Local\Programs\Python\Python38-32\lib\site-packages\sqlalchemy\util\compat.py", line 153, in reraise
    raise value
  File "C:\Users\alejo\AppData\Local\Programs\Python\Python38-32\lib\site-packages\sqlalchemy\pool\impl.py", line 136, in _do_get
    return self._create_connection()
  File "C:\Users\alejo\AppData\Local\Programs\Python\Python38-32\lib\site-packages\sqlalchemy\pool\base.py", line 308, in _create_connection
    return _ConnectionRecord(self)
  File "C:\Users\alejo\AppData\Local\Programs\Python\Python38-32\lib\site-packages\sqlalchemy\pool\base.py", line 437, in __init__
    self.__connect(first_connect_check=True)
  File "C:\Users\alejo\AppData\Local\Programs\Python\Python38-32\lib\site-packages\sqlalchemy\pool\base.py", line 639, in __connect
    connection = pool._invoke_creator(self)
  File "C:\Users\alejo\AppData\Local\Programs\Python\Python38-32\lib\site-packages\sqlalchemy\engine\strategies.py", line 114, in connect
    return dialect.connect(*cargs, **cparams)
  File "C:\Users\alejo\AppData\Local\Programs\Python\Python38-32\lib\site-packages\sqlalchemy\engine\default.py", line 481, in connect
    return self.dbapi.connect(*cargs, **cparams)
  File "C:\Users\alejo\AppData\Local\Programs\Python\Python38-32\lib\site-packages\psycopg2\__init__.py", line 126, in connect
    conn = _connect(dsn, connection_factory=connection_factory, **kwasync)
psycopg2.OperationalError: FATAL:  database "invitame_una_cerveza" does not exist


The above exception was the direct cause of the following exception:

Traceback (most recent call last):
  File "servicio.py", line 432, in create_dml
    proxy.create_ddl()
  File "C:\Users\alejo\Documents\Personal\Proyectos\Berap\invitame_una_cerveza\Python\proxy.py", line 56, in create_ddl
    ddl.data_definition_language(self.engine)
  File "C:\Users\alejo\Documents\Personal\Proyectos\Berap\invitame_una_cerveza\Python\ddl.py", line 151, in data_definition_language
    self.metadata.create_all(engine)
  File "C:\Users\alejo\AppData\Local\Programs\Python\Python38-32\lib\site-packages\sqlalchemy\sql\schema.py", line 4303, in create_all
    bind._run_visitor(
  File "C:\Users\alejo\AppData\Local\Programs\Python\Python38-32\lib\site-packages\sqlalchemy\engine\base.py", line 2045, in _run_visitor
    with self._optional_conn_ctx_manager(connection) as conn:
  File "C:\Users\alejo\AppData\Local\Programs\Python\Python38-32\lib\contextlib.py", line 113, in __enter__
    return next(self.gen)
  File "C:\Users\alejo\AppData\Local\Programs\Python\Python38-32\lib\site-packages\sqlalchemy\engine\base.py", line 2037, in _optional_conn_ctx_manager
    with self._contextual_connect() as conn:
  File "C:\Users\alejo\AppData\Local\Programs\Python\Python38-32\lib\site-packages\sqlalchemy\engine\base.py", line 2239, in _contextual_connect
    self._wrap_pool_connect(self.pool.connect, None),
  File "C:\Users\alejo\AppData\Local\Programs\Python\Python38-32\lib\site-packages\sqlalchemy\engine\base.py", line 2278, in _wrap_pool_connect
    Connection._handle_dbapi_exception_noconnection(
  File "C:\Users\alejo\AppData\Local\Programs\Python\Python38-32\lib\site-packages\sqlalchemy\engine\base.py", line 1544, in _handle_dbapi_exception_noconnection
    util.raise_from_cause(sqlalchemy_exception, exc_info)
  File "C:\Users\alejo\AppData\Local\Programs\Python\Python38-32\lib\site-packages\sqlalchemy\util\compat.py", line 398, in raise_from_cause
    reraise(type(exception), exception, tb=exc_tb, cause=cause)
  File "C:\Users\alejo\AppData\Local\Programs\Python\Python38-32\lib\site-packages\sqlalchemy\util\compat.py", line 152, in reraise
    raise value.with_traceback(tb)
  File "C:\Users\alejo\AppData\Local\Programs\Python\Python38-32\lib\site-packages\sqlalchemy\engine\base.py", line 2275, in _wrap_pool_connect
    return fn()
  File "C:\Users\alejo\AppData\Local\Programs\Python\Python38-32\lib\site-packages\sqlalchemy\pool\base.py", line 363, in connect
    return _ConnectionFairy._checkout(self)
  File "C:\Users\alejo\AppData\Local\Programs\Python\Python38-32\lib\site-packages\sqlalchemy\pool\base.py", line 760, in _checkout
    fairy = _ConnectionRecord.checkout(pool)
  File "C:\Users\alejo\AppData\Local\Programs\Python\Python38-32\lib\site-packages\sqlalchemy\pool\base.py", line 492, in checkout
    rec = pool._do_get()
  File "C:\Users\alejo\AppData\Local\Programs\Python\Python38-32\lib\site-packages\sqlalchemy\pool\impl.py", line 139, in _do_get
    self._dec_overflow()
  File "C:\Users\alejo\AppData\Local\Programs\Python\Python38-32\lib\site-packages\sqlalchemy\util\langhelpers.py", line 68, in __exit__
    compat.reraise(exc_type, exc_value, exc_tb)
  File "C:\Users\alejo\AppData\Local\Programs\Python\Python38-32\lib\site-packages\sqlalchemy\util\compat.py", line 153, in reraise
    raise value
  File "C:\Users\alejo\AppData\Local\Programs\Python\Python38-32\lib\site-packages\sqlalchemy\pool\impl.py", line 136, in _do_get
    return self._create_connection()
  File "C:\Users\alejo\AppData\Local\Programs\Python\Python38-32\lib\site-packages\sqlalchemy\pool\base.py", line 308, in _create_connection
    return _ConnectionRecord(self)
  File "C:\Users\alejo\AppData\Local\Programs\Python\Python38-32\lib\site-packages\sqlalchemy\pool\base.py", line 437, in __init__
    self.__connect(first_connect_check=True)
  File "C:\Users\alejo\AppData\Local\Programs\Python\Python38-32\lib\site-packages\sqlalchemy\pool\base.py", line 639, in __connect
    connection = pool._invoke_creator(self)
  File "C:\Users\alejo\AppData\Local\Programs\Python\Python38-32\lib\site-packages\sqlalchemy\engine\strategies.py", line 114, in connect
    return dialect.connect(*cargs, **cparams)
  File "C:\Users\alejo\AppData\Local\Programs\Python\Python38-32\lib\site-packages\sqlalchemy\engine\default.py", line 481, in connect
    return self.dbapi.connect(*cargs, **cparams)
  File "C:\Users\alejo\AppData\Local\Programs\Python\Python38-32\lib\site-packages\psycopg2\__init__.py", line 126, in connect
    conn = _connect(dsn, connection_factory=connection_factory, **kwasync)
sqlalchemy.exc.OperationalError: (psycopg2.OperationalError) FATAL:  database "invitame_una_cerveza" does not exist

(Background on this error at: http://sqlalche.me/e/e3q8)

During handling of the above exception, another exception occurred:

Traceback (most recent call last):
  File "C:\Users\alejo\AppData\Local\Programs\Python\Python38-32\lib\site-packages\flask\app.py", line 2446, in wsgi_app
    response = self.full_dispatch_request()
  File "C:\Users\alejo\AppData\Local\Programs\Python\Python38-32\lib\site-packages\flask\app.py", line 1951, in full_dispatch_request
    rv = self.handle_user_exception(e)
  File "C:\Users\alejo\AppData\Local\Programs\Python\Python38-32\lib\site-packages\flask_cors\extension.py", line 161, in wrapped_function
    return cors_after_request(app.make_response(f(*args, **kwargs)))
  File "C:\Users\alejo\AppData\Local\Programs\Python\Python38-32\lib\site-packages\flask\app.py", line 1820, in handle_user_exception
    reraise(exc_type, exc_value, tb)
  File "C:\Users\alejo\AppData\Local\Programs\Python\Python38-32\lib\site-packages\flask\_compat.py", line 39, in reraise
    raise value
  File "C:\Users\alejo\AppData\Local\Programs\Python\Python38-32\lib\site-packages\flask\app.py", line 1949, in full_dispatch_request
    rv = self.dispatch_request()
  File "C:\Users\alejo\AppData\Local\Programs\Python\Python38-32\lib\site-packages\flask\app.py", line 1935, in dispatch_request
    return self.view_functions[rule.endpoint](**req.view_args)
  File "C:\Users\alejo\AppData\Local\Programs\Python\Python38-32\lib\site-packages\flask_cors\decorator.py", line 128, in wrapped_function
    resp = make_response(f(*args, **kwargs))
  File "servicio.py", line 436, in create_dml
    logging.debug("Error: "+ _excep)
TypeError: can only concatenate str (not "OperationalError") to str
INFO:werkzeug:127.0.0.1 - - [18/May/2020 17:47:02] "[35m[1mGET /create_database_dml HTTP/1.1[0m" 500 -
DEBUG:root:Engine created!
DEBUG:root:Database no exists. we going to create it!
ERROR:servicio:Exception on /create_database_dml [GET]
Traceback (most recent call last):
  File "C:\Users\alejo\AppData\Local\Programs\Python\Python38-32\lib\site-packages\sqlalchemy\engine\base.py", line 2275, in _wrap_pool_connect
    return fn()
  File "C:\Users\alejo\AppData\Local\Programs\Python\Python38-32\lib\site-packages\sqlalchemy\pool\base.py", line 363, in connect
    return _ConnectionFairy._checkout(self)
  File "C:\Users\alejo\AppData\Local\Programs\Python\Python38-32\lib\site-packages\sqlalchemy\pool\base.py", line 760, in _checkout
    fairy = _ConnectionRecord.checkout(pool)
  File "C:\Users\alejo\AppData\Local\Programs\Python\Python38-32\lib\site-packages\sqlalchemy\pool\base.py", line 492, in checkout
    rec = pool._do_get()
  File "C:\Users\alejo\AppData\Local\Programs\Python\Python38-32\lib\site-packages\sqlalchemy\pool\impl.py", line 139, in _do_get
    self._dec_overflow()
  File "C:\Users\alejo\AppData\Local\Programs\Python\Python38-32\lib\site-packages\sqlalchemy\util\langhelpers.py", line 68, in __exit__
    compat.reraise(exc_type, exc_value, exc_tb)
  File "C:\Users\alejo\AppData\Local\Programs\Python\Python38-32\lib\site-packages\sqlalchemy\util\compat.py", line 153, in reraise
    raise value
  File "C:\Users\alejo\AppData\Local\Programs\Python\Python38-32\lib\site-packages\sqlalchemy\pool\impl.py", line 136, in _do_get
    return self._create_connection()
  File "C:\Users\alejo\AppData\Local\Programs\Python\Python38-32\lib\site-packages\sqlalchemy\pool\base.py", line 308, in _create_connection
    return _ConnectionRecord(self)
  File "C:\Users\alejo\AppData\Local\Programs\Python\Python38-32\lib\site-packages\sqlalchemy\pool\base.py", line 437, in __init__
    self.__connect(first_connect_check=True)
  File "C:\Users\alejo\AppData\Local\Programs\Python\Python38-32\lib\site-packages\sqlalchemy\pool\base.py", line 639, in __connect
    connection = pool._invoke_creator(self)
  File "C:\Users\alejo\AppData\Local\Programs\Python\Python38-32\lib\site-packages\sqlalchemy\engine\strategies.py", line 114, in connect
    return dialect.connect(*cargs, **cparams)
  File "C:\Users\alejo\AppData\Local\Programs\Python\Python38-32\lib\site-packages\sqlalchemy\engine\default.py", line 481, in connect
    return self.dbapi.connect(*cargs, **cparams)
  File "C:\Users\alejo\AppData\Local\Programs\Python\Python38-32\lib\site-packages\psycopg2\__init__.py", line 126, in connect
    conn = _connect(dsn, connection_factory=connection_factory, **kwasync)
psycopg2.OperationalError: FATAL:  database "invitame_una_cerveza" does not exist


The above exception was the direct cause of the following exception:

Traceback (most recent call last):
  File "servicio.py", line 432, in create_dml
    proxy.create_ddl()
  File "C:\Users\alejo\Documents\Personal\Proyectos\Berap\invitame_una_cerveza\Python\proxy.py", line 56, in create_ddl
    ddl.data_definition_language(self.engine)
  File "C:\Users\alejo\Documents\Personal\Proyectos\Berap\invitame_una_cerveza\Python\ddl.py", line 151, in data_definition_language
    self.metadata.create_all(engine)
  File "C:\Users\alejo\AppData\Local\Programs\Python\Python38-32\lib\site-packages\sqlalchemy\sql\schema.py", line 4303, in create_all
    bind._run_visitor(
  File "C:\Users\alejo\AppData\Local\Programs\Python\Python38-32\lib\site-packages\sqlalchemy\engine\base.py", line 2045, in _run_visitor
    with self._optional_conn_ctx_manager(connection) as conn:
  File "C:\Users\alejo\AppData\Local\Programs\Python\Python38-32\lib\contextlib.py", line 113, in __enter__
    return next(self.gen)
  File "C:\Users\alejo\AppData\Local\Programs\Python\Python38-32\lib\site-packages\sqlalchemy\engine\base.py", line 2037, in _optional_conn_ctx_manager
    with self._contextual_connect() as conn:
  File "C:\Users\alejo\AppData\Local\Programs\Python\Python38-32\lib\site-packages\sqlalchemy\engine\base.py", line 2239, in _contextual_connect
    self._wrap_pool_connect(self.pool.connect, None),
  File "C:\Users\alejo\AppData\Local\Programs\Python\Python38-32\lib\site-packages\sqlalchemy\engine\base.py", line 2278, in _wrap_pool_connect
    Connection._handle_dbapi_exception_noconnection(
  File "C:\Users\alejo\AppData\Local\Programs\Python\Python38-32\lib\site-packages\sqlalchemy\engine\base.py", line 1544, in _handle_dbapi_exception_noconnection
    util.raise_from_cause(sqlalchemy_exception, exc_info)
  File "C:\Users\alejo\AppData\Local\Programs\Python\Python38-32\lib\site-packages\sqlalchemy\util\compat.py", line 398, in raise_from_cause
    reraise(type(exception), exception, tb=exc_tb, cause=cause)
  File "C:\Users\alejo\AppData\Local\Programs\Python\Python38-32\lib\site-packages\sqlalchemy\util\compat.py", line 152, in reraise
    raise value.with_traceback(tb)
  File "C:\Users\alejo\AppData\Local\Programs\Python\Python38-32\lib\site-packages\sqlalchemy\engine\base.py", line 2275, in _wrap_pool_connect
    return fn()
  File "C:\Users\alejo\AppData\Local\Programs\Python\Python38-32\lib\site-packages\sqlalchemy\pool\base.py", line 363, in connect
    return _ConnectionFairy._checkout(self)
  File "C:\Users\alejo\AppData\Local\Programs\Python\Python38-32\lib\site-packages\sqlalchemy\pool\base.py", line 760, in _checkout
    fairy = _ConnectionRecord.checkout(pool)
  File "C:\Users\alejo\AppData\Local\Programs\Python\Python38-32\lib\site-packages\sqlalchemy\pool\base.py", line 492, in checkout
    rec = pool._do_get()
  File "C:\Users\alejo\AppData\Local\Programs\Python\Python38-32\lib\site-packages\sqlalchemy\pool\impl.py", line 139, in _do_get
    self._dec_overflow()
  File "C:\Users\alejo\AppData\Local\Programs\Python\Python38-32\lib\site-packages\sqlalchemy\util\langhelpers.py", line 68, in __exit__
    compat.reraise(exc_type, exc_value, exc_tb)
  File "C:\Users\alejo\AppData\Local\Programs\Python\Python38-32\lib\site-packages\sqlalchemy\util\compat.py", line 153, in reraise
    raise value
  File "C:\Users\alejo\AppData\Local\Programs\Python\Python38-32\lib\site-packages\sqlalchemy\pool\impl.py", line 136, in _do_get
    return self._create_connection()
  File "C:\Users\alejo\AppData\Local\Programs\Python\Python38-32\lib\site-packages\sqlalchemy\pool\base.py", line 308, in _create_connection
    return _ConnectionRecord(self)
  File "C:\Users\alejo\AppData\Local\Programs\Python\Python38-32\lib\site-packages\sqlalchemy\pool\base.py", line 437, in __init__
    self.__connect(first_connect_check=True)
  File "C:\Users\alejo\AppData\Local\Programs\Python\Python38-32\lib\site-packages\sqlalchemy\pool\base.py", line 639, in __connect
    connection = pool._invoke_creator(self)
  File "C:\Users\alejo\AppData\Local\Programs\Python\Python38-32\lib\site-packages\sqlalchemy\engine\strategies.py", line 114, in connect
    return dialect.connect(*cargs, **cparams)
  File "C:\Users\alejo\AppData\Local\Programs\Python\Python38-32\lib\site-packages\sqlalchemy\engine\default.py", line 481, in connect
    return self.dbapi.connect(*cargs, **cparams)
  File "C:\Users\alejo\AppData\Local\Programs\Python\Python38-32\lib\site-packages\psycopg2\__init__.py", line 126, in connect
    conn = _connect(dsn, connection_factory=connection_factory, **kwasync)
sqlalchemy.exc.OperationalError: (psycopg2.OperationalError) FATAL:  database "invitame_una_cerveza" does not exist

(Background on this error at: http://sqlalche.me/e/e3q8)

During handling of the above exception, another exception occurred:

Traceback (most recent call last):
  File "C:\Users\alejo\AppData\Local\Programs\Python\Python38-32\lib\site-packages\flask\app.py", line 2446, in wsgi_app
    response = self.full_dispatch_request()
  File "C:\Users\alejo\AppData\Local\Programs\Python\Python38-32\lib\site-packages\flask\app.py", line 1951, in full_dispatch_request
    rv = self.handle_user_exception(e)
  File "C:\Users\alejo\AppData\Local\Programs\Python\Python38-32\lib\site-packages\flask_cors\extension.py", line 161, in wrapped_function
    return cors_after_request(app.make_response(f(*args, **kwargs)))
  File "C:\Users\alejo\AppData\Local\Programs\Python\Python38-32\lib\site-packages\flask\app.py", line 1820, in handle_user_exception
    reraise(exc_type, exc_value, tb)
  File "C:\Users\alejo\AppData\Local\Programs\Python\Python38-32\lib\site-packages\flask\_compat.py", line 39, in reraise
    raise value
  File "C:\Users\alejo\AppData\Local\Programs\Python\Python38-32\lib\site-packages\flask\app.py", line 1949, in full_dispatch_request
    rv = self.dispatch_request()
  File "C:\Users\alejo\AppData\Local\Programs\Python\Python38-32\lib\site-packages\flask\app.py", line 1935, in dispatch_request
    return self.view_functions[rule.endpoint](**req.view_args)
  File "C:\Users\alejo\AppData\Local\Programs\Python\Python38-32\lib\site-packages\flask_cors\decorator.py", line 128, in wrapped_function
    resp = make_response(f(*args, **kwargs))
  File "servicio.py", line 436, in create_dml
    logging.debug("Error: "+ _excep)
TypeError: can only concatenate str (not "OperationalError") to str
INFO:werkzeug:127.0.0.1 - - [18/May/2020 17:47:07] "[35m[1mGET /create_database_dml HTTP/1.1[0m" 500 -
INFO:werkzeug: * Running on http://127.0.0.1:5000/ (Press CTRL+C to quit)
DEBUG:root:Engine created!
DEBUG:root:Database no exists. we going to create it!
DEBUG:root:Database created!
DEBUG:root:DataDefinitionLanguage created!
DEBUG:root:DefaultConnection full
DEBUG:root:DataModelingLanguage begin!
DEBUG:root:dumps
ERROR:servicio:Exception on /create_database_dml [GET]
Traceback (most recent call last):
  File "C:\Users\alejo\AppData\Local\Programs\Python\Python38-32\lib\site-packages\sqlalchemy\engine\base.py", line 1248, in _execute_context
    self.dialect.do_execute(
  File "C:\Users\alejo\AppData\Local\Programs\Python\Python38-32\lib\site-packages\sqlalchemy\engine\default.py", line 580, in do_execute
    cursor.execute(statement, parameters)
psycopg2.errors.NotNullViolation: null value in column "duration" violates not-null constraint
DETAIL:  Failing row contains (1, null, 1, 2020-05-18 17:48:54.392832, 2020-05-18 17:48:54.392832, Alejo).


The above exception was the direct cause of the following exception:

Traceback (most recent call last):
  File "servicio.py", line 433, in create_dml
    proxy.create_dml()
  File "C:\Users\alejo\Documents\Personal\Proyectos\Berap\invitame_una_cerveza\Python\proxy.py", line 64, in create_dml
    dml.create_dml()
  File "C:\Users\alejo\Documents\Personal\Proyectos\Berap\invitame_una_cerveza\Python\dml.py", line 68, in create_dml
    self.default_connection.get_beer_connection().session.commit()
  File "C:\Users\alejo\AppData\Local\Programs\Python\Python38-32\lib\site-packages\sqlalchemy\orm\session.py", line 1027, in commit
    self.transaction.commit()
  File "C:\Users\alejo\AppData\Local\Programs\Python\Python38-32\lib\site-packages\sqlalchemy\orm\session.py", line 494, in commit
    self._prepare_impl()
  File "C:\Users\alejo\AppData\Local\Programs\Python\Python38-32\lib\site-packages\sqlalchemy\orm\session.py", line 473, in _prepare_impl
    self.session.flush()
  File "C:\Users\alejo\AppData\Local\Programs\Python\Python38-32\lib\site-packages\sqlalchemy\orm\session.py", line 2470, in flush
    self._flush(objects)
  File "C:\Users\alejo\AppData\Local\Programs\Python\Python38-32\lib\site-packages\sqlalchemy\orm\session.py", line 2608, in _flush
    transaction.rollback(_capture_exception=True)
  File "C:\Users\alejo\AppData\Local\Programs\Python\Python38-32\lib\site-packages\sqlalchemy\util\langhelpers.py", line 68, in __exit__
    compat.reraise(exc_type, exc_value, exc_tb)
  File "C:\Users\alejo\AppData\Local\Programs\Python\Python38-32\lib\site-packages\sqlalchemy\util\compat.py", line 153, in reraise
    raise value
  File "C:\Users\alejo\AppData\Local\Programs\Python\Python38-32\lib\site-packages\sqlalchemy\orm\session.py", line 2568, in _flush
    flush_context.execute()
  File "C:\Users\alejo\AppData\Local\Programs\Python\Python38-32\lib\site-packages\sqlalchemy\orm\unitofwork.py", line 422, in execute
    rec.execute(self)
  File "C:\Users\alejo\AppData\Local\Programs\Python\Python38-32\lib\site-packages\sqlalchemy\orm\unitofwork.py", line 586, in execute
    persistence.save_obj(
  File "C:\Users\alejo\AppData\Local\Programs\Python\Python38-32\lib\site-packages\sqlalchemy\orm\persistence.py", line 239, in save_obj
    _emit_insert_statements(
  File "C:\Users\alejo\AppData\Local\Programs\Python\Python38-32\lib\site-packages\sqlalchemy\orm\persistence.py", line 1136, in _emit_insert_statements
    result = cached_connections[connection].execute(
  File "C:\Users\alejo\AppData\Local\Programs\Python\Python38-32\lib\site-packages\sqlalchemy\engine\base.py", line 988, in execute
    return meth(self, multiparams, params)
  File "C:\Users\alejo\AppData\Local\Programs\Python\Python38-32\lib\site-packages\sqlalchemy\sql\elements.py", line 287, in _execute_on_connection
    return connection._execute_clauseelement(self, multiparams, params)
  File "C:\Users\alejo\AppData\Local\Programs\Python\Python38-32\lib\site-packages\sqlalchemy\engine\base.py", line 1101, in _execute_clauseelement
    ret = self._execute_context(
  File "C:\Users\alejo\AppData\Local\Programs\Python\Python38-32\lib\site-packages\sqlalchemy\engine\base.py", line 1252, in _execute_context
    self._handle_dbapi_exception(
  File "C:\Users\alejo\AppData\Local\Programs\Python\Python38-32\lib\site-packages\sqlalchemy\engine\base.py", line 1473, in _handle_dbapi_exception
    util.raise_from_cause(sqlalchemy_exception, exc_info)
  File "C:\Users\alejo\AppData\Local\Programs\Python\Python38-32\lib\site-packages\sqlalchemy\util\compat.py", line 398, in raise_from_cause
    reraise(type(exception), exception, tb=exc_tb, cause=cause)
  File "C:\Users\alejo\AppData\Local\Programs\Python\Python38-32\lib\site-packages\sqlalchemy\util\compat.py", line 152, in reraise
    raise value.with_traceback(tb)
  File "C:\Users\alejo\AppData\Local\Programs\Python\Python38-32\lib\site-packages\sqlalchemy\engine\base.py", line 1248, in _execute_context
    self.dialect.do_execute(
  File "C:\Users\alejo\AppData\Local\Programs\Python\Python38-32\lib\site-packages\sqlalchemy\engine\default.py", line 580, in do_execute
    cursor.execute(statement, parameters)
sqlalchemy.exc.IntegrityError: (psycopg2.errors.NotNullViolation) null value in column "duration" violates not-null constraint
DETAIL:  Failing row contains (1, null, 1, 2020-05-18 17:48:54.392832, 2020-05-18 17:48:54.392832, Alejo).

[SQL: INSERT INTO public."PROMOTION" (created_at, updated_at, last_updated_by, beer_id) VALUES (%(created_at)s, %(updated_at)s, %(last_updated_by)s, %(beer_id)s) RETURNING public."PROMOTION".id]
[parameters: {'created_at': datetime.datetime(2020, 5, 18, 17, 48, 54, 392832), 'updated_at': datetime.datetime(2020, 5, 18, 17, 48, 54, 392832), 'last_updated_by': 'Alejo', 'beer_id': 1}]
(Background on this error at: http://sqlalche.me/e/gkpj)

During handling of the above exception, another exception occurred:

Traceback (most recent call last):
  File "C:\Users\alejo\AppData\Local\Programs\Python\Python38-32\lib\site-packages\flask\app.py", line 2446, in wsgi_app
    response = self.full_dispatch_request()
  File "C:\Users\alejo\AppData\Local\Programs\Python\Python38-32\lib\site-packages\flask\app.py", line 1951, in full_dispatch_request
    rv = self.handle_user_exception(e)
  File "C:\Users\alejo\AppData\Local\Programs\Python\Python38-32\lib\site-packages\flask_cors\extension.py", line 161, in wrapped_function
    return cors_after_request(app.make_response(f(*args, **kwargs)))
  File "C:\Users\alejo\AppData\Local\Programs\Python\Python38-32\lib\site-packages\flask\app.py", line 1820, in handle_user_exception
    reraise(exc_type, exc_value, tb)
  File "C:\Users\alejo\AppData\Local\Programs\Python\Python38-32\lib\site-packages\flask\_compat.py", line 39, in reraise
    raise value
  File "C:\Users\alejo\AppData\Local\Programs\Python\Python38-32\lib\site-packages\flask\app.py", line 1949, in full_dispatch_request
    rv = self.dispatch_request()
  File "C:\Users\alejo\AppData\Local\Programs\Python\Python38-32\lib\site-packages\flask\app.py", line 1935, in dispatch_request
    return self.view_functions[rule.endpoint](**req.view_args)
  File "C:\Users\alejo\AppData\Local\Programs\Python\Python38-32\lib\site-packages\flask_cors\decorator.py", line 128, in wrapped_function
    resp = make_response(f(*args, **kwargs))
  File "servicio.py", line 436, in create_dml
    logging.debug("Error: "+ _excep)
TypeError: can only concatenate str (not "IntegrityError") to str
INFO:werkzeug:127.0.0.1 - - [18/May/2020 17:48:54] "[35m[1mGET /create_database_dml HTTP/1.1[0m" 500 -
INFO:werkzeug: * Running on http://127.0.0.1:5000/ (Press CTRL+C to quit)
DEBUG:root:Engine created!
DEBUG:root:Database no exists. we going to create it!
DEBUG:root:Database created!
DEBUG:root:DataDefinitionLanguage created!
DEBUG:root:DefaultConnection full
DEBUG:root:DataModelingLanguage begin!
DEBUG:root:dumps
ERROR:servicio:Exception on /create_database_dml [GET]
Traceback (most recent call last):
  File "servicio.py", line 433, in create_dml
    proxy.create_dml()
  File "C:\Users\alejo\Documents\Personal\Proyectos\Berap\invitame_una_cerveza\Python\proxy.py", line 64, in create_dml
    dml.create_dml()
  File "C:\Users\alejo\Documents\Personal\Proyectos\Berap\invitame_una_cerveza\Python\dml.py", line 61, in create_dml
    promotion = Promotion(beer.id, 8, Constant.user)
TypeError: __init__() takes 3 positional arguments but 4 were given

During handling of the above exception, another exception occurred:

Traceback (most recent call last):
  File "C:\Users\alejo\AppData\Local\Programs\Python\Python38-32\lib\site-packages\flask\app.py", line 2446, in wsgi_app
    response = self.full_dispatch_request()
  File "C:\Users\alejo\AppData\Local\Programs\Python\Python38-32\lib\site-packages\flask\app.py", line 1951, in full_dispatch_request
    rv = self.handle_user_exception(e)
  File "C:\Users\alejo\AppData\Local\Programs\Python\Python38-32\lib\site-packages\flask_cors\extension.py", line 161, in wrapped_function
    return cors_after_request(app.make_response(f(*args, **kwargs)))
  File "C:\Users\alejo\AppData\Local\Programs\Python\Python38-32\lib\site-packages\flask\app.py", line 1820, in handle_user_exception
    reraise(exc_type, exc_value, tb)
  File "C:\Users\alejo\AppData\Local\Programs\Python\Python38-32\lib\site-packages\flask\_compat.py", line 39, in reraise
    raise value
  File "C:\Users\alejo\AppData\Local\Programs\Python\Python38-32\lib\site-packages\flask\app.py", line 1949, in full_dispatch_request
    rv = self.dispatch_request()
  File "C:\Users\alejo\AppData\Local\Programs\Python\Python38-32\lib\site-packages\flask\app.py", line 1935, in dispatch_request
    return self.view_functions[rule.endpoint](**req.view_args)
  File "C:\Users\alejo\AppData\Local\Programs\Python\Python38-32\lib\site-packages\flask_cors\decorator.py", line 128, in wrapped_function
    resp = make_response(f(*args, **kwargs))
  File "servicio.py", line 436, in create_dml
    logging.debug("Error: "+ _excep)
TypeError: can only concatenate str (not "TypeError") to str
INFO:werkzeug:127.0.0.1 - - [18/May/2020 17:52:54] "[35m[1mGET /create_database_dml HTTP/1.1[0m" 500 -
ERROR:sqlalchemy.pool.impl.QueuePool:Exception during reset or similar
Traceback (most recent call last):
  File "C:\Users\alejo\AppData\Local\Programs\Python\Python38-32\lib\site-packages\sqlalchemy\pool\base.py", line 680, in _finalize_fairy
    fairy._reset(pool)
  File "C:\Users\alejo\AppData\Local\Programs\Python\Python38-32\lib\site-packages\sqlalchemy\pool\base.py", line 867, in _reset
    pool._dialect.do_rollback(self)
  File "C:\Users\alejo\AppData\Local\Programs\Python\Python38-32\lib\site-packages\sqlalchemy\engine\default.py", line 530, in do_rollback
    dbapi_connection.rollback()
psycopg2.OperationalError: server closed the connection unexpectedly
	This probably means the server terminated abnormally
	before or while processing the request.

INFO:werkzeug: * Running on http://127.0.0.1:5000/ (Press CTRL+C to quit)
DEBUG:root:Engine created!
DEBUG:root:Database no exists. we going to create it!
DEBUG:root:Database created!
DEBUG:root:DataDefinitionLanguage created!
DEBUG:root:DefaultConnection full
DEBUG:root:DataModelingLanguage begin!
DEBUG:root:dumps
ERROR:servicio:Exception on /create_database_dml [GET]
Traceback (most recent call last):
  File "C:\Users\alejo\AppData\Local\Programs\Python\Python38-32\lib\site-packages\sqlalchemy\engine\base.py", line 1248, in _execute_context
    self.dialect.do_execute(
  File "C:\Users\alejo\AppData\Local\Programs\Python\Python38-32\lib\site-packages\sqlalchemy\engine\default.py", line 580, in do_execute
    cursor.execute(statement, parameters)
psycopg2.errors.ForeignKeyViolation: insert or update on table "PROMOTION" violates foreign key constraint "PROMOTION_beer_id_fkey"
DETAIL:  Key (beer_id)=(8) is not present in table "BEER".


The above exception was the direct cause of the following exception:

Traceback (most recent call last):
  File "servicio.py", line 433, in create_dml
    proxy.create_dml()
  File "C:\Users\alejo\Documents\Personal\Proyectos\Berap\invitame_una_cerveza\Python\proxy.py", line 64, in create_dml
    dml.create_dml()
  File "C:\Users\alejo\Documents\Personal\Proyectos\Berap\invitame_una_cerveza\Python\dml.py", line 68, in create_dml
    self.default_connection.get_beer_connection().session.commit()
  File "C:\Users\alejo\AppData\Local\Programs\Python\Python38-32\lib\site-packages\sqlalchemy\orm\session.py", line 1027, in commit
    self.transaction.commit()
  File "C:\Users\alejo\AppData\Local\Programs\Python\Python38-32\lib\site-packages\sqlalchemy\orm\session.py", line 494, in commit
    self._prepare_impl()
  File "C:\Users\alejo\AppData\Local\Programs\Python\Python38-32\lib\site-packages\sqlalchemy\orm\session.py", line 473, in _prepare_impl
    self.session.flush()
  File "C:\Users\alejo\AppData\Local\Programs\Python\Python38-32\lib\site-packages\sqlalchemy\orm\session.py", line 2470, in flush
    self._flush(objects)
  File "C:\Users\alejo\AppData\Local\Programs\Python\Python38-32\lib\site-packages\sqlalchemy\orm\session.py", line 2608, in _flush
    transaction.rollback(_capture_exception=True)
  File "C:\Users\alejo\AppData\Local\Programs\Python\Python38-32\lib\site-packages\sqlalchemy\util\langhelpers.py", line 68, in __exit__
    compat.reraise(exc_type, exc_value, exc_tb)
  File "C:\Users\alejo\AppData\Local\Programs\Python\Python38-32\lib\site-packages\sqlalchemy\util\compat.py", line 153, in reraise
    raise value
  File "C:\Users\alejo\AppData\Local\Programs\Python\Python38-32\lib\site-packages\sqlalchemy\orm\session.py", line 2568, in _flush
    flush_context.execute()
  File "C:\Users\alejo\AppData\Local\Programs\Python\Python38-32\lib\site-packages\sqlalchemy\orm\unitofwork.py", line 422, in execute
    rec.execute(self)
  File "C:\Users\alejo\AppData\Local\Programs\Python\Python38-32\lib\site-packages\sqlalchemy\orm\unitofwork.py", line 586, in execute
    persistence.save_obj(
  File "C:\Users\alejo\AppData\Local\Programs\Python\Python38-32\lib\site-packages\sqlalchemy\orm\persistence.py", line 239, in save_obj
    _emit_insert_statements(
  File "C:\Users\alejo\AppData\Local\Programs\Python\Python38-32\lib\site-packages\sqlalchemy\orm\persistence.py", line 1136, in _emit_insert_statements
    result = cached_connections[connection].execute(
  File "C:\Users\alejo\AppData\Local\Programs\Python\Python38-32\lib\site-packages\sqlalchemy\engine\base.py", line 988, in execute
    return meth(self, multiparams, params)
  File "C:\Users\alejo\AppData\Local\Programs\Python\Python38-32\lib\site-packages\sqlalchemy\sql\elements.py", line 287, in _execute_on_connection
    return connection._execute_clauseelement(self, multiparams, params)
  File "C:\Users\alejo\AppData\Local\Programs\Python\Python38-32\lib\site-packages\sqlalchemy\engine\base.py", line 1101, in _execute_clauseelement
    ret = self._execute_context(
  File "C:\Users\alejo\AppData\Local\Programs\Python\Python38-32\lib\site-packages\sqlalchemy\engine\base.py", line 1252, in _execute_context
    self._handle_dbapi_exception(
  File "C:\Users\alejo\AppData\Local\Programs\Python\Python38-32\lib\site-packages\sqlalchemy\engine\base.py", line 1473, in _handle_dbapi_exception
    util.raise_from_cause(sqlalchemy_exception, exc_info)
  File "C:\Users\alejo\AppData\Local\Programs\Python\Python38-32\lib\site-packages\sqlalchemy\util\compat.py", line 398, in raise_from_cause
    reraise(type(exception), exception, tb=exc_tb, cause=cause)
  File "C:\Users\alejo\AppData\Local\Programs\Python\Python38-32\lib\site-packages\sqlalchemy\util\compat.py", line 152, in reraise
    raise value.with_traceback(tb)
  File "C:\Users\alejo\AppData\Local\Programs\Python\Python38-32\lib\site-packages\sqlalchemy\engine\base.py", line 1248, in _execute_context
    self.dialect.do_execute(
  File "C:\Users\alejo\AppData\Local\Programs\Python\Python38-32\lib\site-packages\sqlalchemy\engine\default.py", line 580, in do_execute
    cursor.execute(statement, parameters)
sqlalchemy.exc.IntegrityError: (psycopg2.errors.ForeignKeyViolation) insert or update on table "PROMOTION" violates foreign key constraint "PROMOTION_beer_id_fkey"
DETAIL:  Key (beer_id)=(8) is not present in table "BEER".

[SQL: INSERT INTO public."PROMOTION" (created_at, updated_at, last_updated_by, duration, beer_id) VALUES (%(created_at)s, %(updated_at)s, %(last_updated_by)s, %(duration)s, %(beer_id)s) RETURNING public."PROMOTION".id]
[parameters: {'created_at': datetime.datetime(2020, 5, 18, 17, 55, 51, 935506), 'updated_at': datetime.datetime(2020, 5, 18, 17, 55, 51, 935506), 'last_updated_by': 'Alejo', 'duration': 1, 'beer_id': 8}]
(Background on this error at: http://sqlalche.me/e/gkpj)

During handling of the above exception, another exception occurred:

Traceback (most recent call last):
  File "C:\Users\alejo\AppData\Local\Programs\Python\Python38-32\lib\site-packages\flask\app.py", line 2446, in wsgi_app
    response = self.full_dispatch_request()
  File "C:\Users\alejo\AppData\Local\Programs\Python\Python38-32\lib\site-packages\flask\app.py", line 1951, in full_dispatch_request
    rv = self.handle_user_exception(e)
  File "C:\Users\alejo\AppData\Local\Programs\Python\Python38-32\lib\site-packages\flask_cors\extension.py", line 161, in wrapped_function
    return cors_after_request(app.make_response(f(*args, **kwargs)))
  File "C:\Users\alejo\AppData\Local\Programs\Python\Python38-32\lib\site-packages\flask\app.py", line 1820, in handle_user_exception
    reraise(exc_type, exc_value, tb)
  File "C:\Users\alejo\AppData\Local\Programs\Python\Python38-32\lib\site-packages\flask\_compat.py", line 39, in reraise
    raise value
  File "C:\Users\alejo\AppData\Local\Programs\Python\Python38-32\lib\site-packages\flask\app.py", line 1949, in full_dispatch_request
    rv = self.dispatch_request()
  File "C:\Users\alejo\AppData\Local\Programs\Python\Python38-32\lib\site-packages\flask\app.py", line 1935, in dispatch_request
    return self.view_functions[rule.endpoint](**req.view_args)
  File "C:\Users\alejo\AppData\Local\Programs\Python\Python38-32\lib\site-packages\flask_cors\decorator.py", line 128, in wrapped_function
    resp = make_response(f(*args, **kwargs))
  File "servicio.py", line 436, in create_dml
    logging.debug("Error: "+ _excep)
TypeError: can only concatenate str (not "IntegrityError") to str
INFO:werkzeug:127.0.0.1 - - [18/May/2020 17:55:51] "[35m[1mGET /create_database_dml HTTP/1.1[0m" 500 -
INFO:werkzeug:127.0.0.1 - - [18/May/2020 17:56:43] "[33mGET /create_dml HTTP/1.1[0m" 404 -
DEBUG:root:Engine created!
DEBUG:root:Begin insert DML!
DEBUG:root:DefaultConnection full
DEBUG:root:DataModelingLanguage begin!
DEBUG:root:dumps
ERROR:servicio:Exception on /create_database_dml [GET]
Traceback (most recent call last):
  File "C:\Users\alejo\AppData\Local\Programs\Python\Python38-32\lib\site-packages\sqlalchemy\engine\base.py", line 1248, in _execute_context
    self.dialect.do_execute(
  File "C:\Users\alejo\AppData\Local\Programs\Python\Python38-32\lib\site-packages\sqlalchemy\engine\default.py", line 580, in do_execute
    cursor.execute(statement, parameters)
psycopg2.errors.ForeignKeyViolation: insert or update on table "PROMOTION" violates foreign key constraint "PROMOTION_beer_id_fkey"
DETAIL:  Key (beer_id)=(8) is not present in table "BEER".


The above exception was the direct cause of the following exception:

Traceback (most recent call last):
  File "servicio.py", line 428, in create_dml
    proxy.create_dml()
  File "C:\Users\alejo\Documents\Personal\Proyectos\Berap\invitame_una_cerveza\Python\proxy.py", line 64, in create_dml
    dml.create_dml()
  File "C:\Users\alejo\Documents\Personal\Proyectos\Berap\invitame_una_cerveza\Python\dml.py", line 68, in create_dml
    self.default_connection.get_beer_connection().session.commit()
  File "C:\Users\alejo\AppData\Local\Programs\Python\Python38-32\lib\site-packages\sqlalchemy\orm\session.py", line 1027, in commit
    self.transaction.commit()
  File "C:\Users\alejo\AppData\Local\Programs\Python\Python38-32\lib\site-packages\sqlalchemy\orm\session.py", line 494, in commit
    self._prepare_impl()
  File "C:\Users\alejo\AppData\Local\Programs\Python\Python38-32\lib\site-packages\sqlalchemy\orm\session.py", line 473, in _prepare_impl
    self.session.flush()
  File "C:\Users\alejo\AppData\Local\Programs\Python\Python38-32\lib\site-packages\sqlalchemy\orm\session.py", line 2470, in flush
    self._flush(objects)
  File "C:\Users\alejo\AppData\Local\Programs\Python\Python38-32\lib\site-packages\sqlalchemy\orm\session.py", line 2608, in _flush
    transaction.rollback(_capture_exception=True)
  File "C:\Users\alejo\AppData\Local\Programs\Python\Python38-32\lib\site-packages\sqlalchemy\util\langhelpers.py", line 68, in __exit__
    compat.reraise(exc_type, exc_value, exc_tb)
  File "C:\Users\alejo\AppData\Local\Programs\Python\Python38-32\lib\site-packages\sqlalchemy\util\compat.py", line 153, in reraise
    raise value
  File "C:\Users\alejo\AppData\Local\Programs\Python\Python38-32\lib\site-packages\sqlalchemy\orm\session.py", line 2568, in _flush
    flush_context.execute()
  File "C:\Users\alejo\AppData\Local\Programs\Python\Python38-32\lib\site-packages\sqlalchemy\orm\unitofwork.py", line 422, in execute
    rec.execute(self)
  File "C:\Users\alejo\AppData\Local\Programs\Python\Python38-32\lib\site-packages\sqlalchemy\orm\unitofwork.py", line 586, in execute
    persistence.save_obj(
  File "C:\Users\alejo\AppData\Local\Programs\Python\Python38-32\lib\site-packages\sqlalchemy\orm\persistence.py", line 239, in save_obj
    _emit_insert_statements(
  File "C:\Users\alejo\AppData\Local\Programs\Python\Python38-32\lib\site-packages\sqlalchemy\orm\persistence.py", line 1136, in _emit_insert_statements
    result = cached_connections[connection].execute(
  File "C:\Users\alejo\AppData\Local\Programs\Python\Python38-32\lib\site-packages\sqlalchemy\engine\base.py", line 988, in execute
    return meth(self, multiparams, params)
  File "C:\Users\alejo\AppData\Local\Programs\Python\Python38-32\lib\site-packages\sqlalchemy\sql\elements.py", line 287, in _execute_on_connection
    return connection._execute_clauseelement(self, multiparams, params)
  File "C:\Users\alejo\AppData\Local\Programs\Python\Python38-32\lib\site-packages\sqlalchemy\engine\base.py", line 1101, in _execute_clauseelement
    ret = self._execute_context(
  File "C:\Users\alejo\AppData\Local\Programs\Python\Python38-32\lib\site-packages\sqlalchemy\engine\base.py", line 1252, in _execute_context
    self._handle_dbapi_exception(
  File "C:\Users\alejo\AppData\Local\Programs\Python\Python38-32\lib\site-packages\sqlalchemy\engine\base.py", line 1473, in _handle_dbapi_exception
    util.raise_from_cause(sqlalchemy_exception, exc_info)
  File "C:\Users\alejo\AppData\Local\Programs\Python\Python38-32\lib\site-packages\sqlalchemy\util\compat.py", line 398, in raise_from_cause
    reraise(type(exception), exception, tb=exc_tb, cause=cause)
  File "C:\Users\alejo\AppData\Local\Programs\Python\Python38-32\lib\site-packages\sqlalchemy\util\compat.py", line 152, in reraise
    raise value.with_traceback(tb)
  File "C:\Users\alejo\AppData\Local\Programs\Python\Python38-32\lib\site-packages\sqlalchemy\engine\base.py", line 1248, in _execute_context
    self.dialect.do_execute(
  File "C:\Users\alejo\AppData\Local\Programs\Python\Python38-32\lib\site-packages\sqlalchemy\engine\default.py", line 580, in do_execute
    cursor.execute(statement, parameters)
sqlalchemy.exc.IntegrityError: (psycopg2.errors.ForeignKeyViolation) insert or update on table "PROMOTION" violates foreign key constraint "PROMOTION_beer_id_fkey"
DETAIL:  Key (beer_id)=(8) is not present in table "BEER".

[SQL: INSERT INTO public."PROMOTION" (created_at, updated_at, last_updated_by, duration, beer_id) VALUES (%(created_at)s, %(updated_at)s, %(last_updated_by)s, %(duration)s, %(beer_id)s) RETURNING public."PROMOTION".id]
[parameters: {'created_at': datetime.datetime(2020, 5, 18, 17, 57, 3, 92624), 'updated_at': datetime.datetime(2020, 5, 18, 17, 57, 3, 92624), 'last_updated_by': 'Alejo', 'duration': 2, 'beer_id': 8}]
(Background on this error at: http://sqlalche.me/e/gkpj)

During handling of the above exception, another exception occurred:

Traceback (most recent call last):
  File "C:\Users\alejo\AppData\Local\Programs\Python\Python38-32\lib\site-packages\flask\app.py", line 2446, in wsgi_app
    response = self.full_dispatch_request()
  File "C:\Users\alejo\AppData\Local\Programs\Python\Python38-32\lib\site-packages\flask\app.py", line 1951, in full_dispatch_request
    rv = self.handle_user_exception(e)
  File "C:\Users\alejo\AppData\Local\Programs\Python\Python38-32\lib\site-packages\flask_cors\extension.py", line 161, in wrapped_function
    return cors_after_request(app.make_response(f(*args, **kwargs)))
  File "C:\Users\alejo\AppData\Local\Programs\Python\Python38-32\lib\site-packages\flask\app.py", line 1820, in handle_user_exception
    reraise(exc_type, exc_value, tb)
  File "C:\Users\alejo\AppData\Local\Programs\Python\Python38-32\lib\site-packages\flask\_compat.py", line 39, in reraise
    raise value
  File "C:\Users\alejo\AppData\Local\Programs\Python\Python38-32\lib\site-packages\flask\app.py", line 1949, in full_dispatch_request
    rv = self.dispatch_request()
  File "C:\Users\alejo\AppData\Local\Programs\Python\Python38-32\lib\site-packages\flask\app.py", line 1935, in dispatch_request
    return self.view_functions[rule.endpoint](**req.view_args)
  File "C:\Users\alejo\AppData\Local\Programs\Python\Python38-32\lib\site-packages\flask_cors\decorator.py", line 128, in wrapped_function
    resp = make_response(f(*args, **kwargs))
  File "servicio.py", line 436, in create_dml
    logging.debug("Error: "+ _excep)
TypeError: can only concatenate str (not "IntegrityError") to str
INFO:werkzeug:127.0.0.1 - - [18/May/2020 17:57:03] "[35m[1mGET /create_database_dml HTTP/1.1[0m" 500 -
INFO:werkzeug: * Running on http://127.0.0.1:5000/ (Press CTRL+C to quit)
DEBUG:root:Engine created!
DEBUG:root:Begin insert DML!
DEBUG:root:DefaultConnection full
DEBUG:root:DataModelingLanguage begin!
DEBUG:root:dumps
DEBUG:root:DataModelingLanguage created!
DEBUG:root:DataModelingLanguage created!
INFO:werkzeug:127.0.0.1 - - [18/May/2020 17:58:14] "[37mGET /create_database_dml HTTP/1.1[0m" 200 -
INFO:werkzeug: * Running on http://127.0.0.1:5000/ (Press CTRL+C to quit)
DEBUG:root:Engine created!
DEBUG:root:Database no exists. we going to create it!
DEBUG:root:Database created!
DEBUG:root:DataDefinitionLanguage created!
DEBUG:root:DefaultConnection full
DEBUG:root:DataModelingLanguage begin!
DEBUG:root:dumps
DEBUG:root:DataModelingLanguage created!
DEBUG:root:DataModelingLanguage created!
INFO:werkzeug:127.0.0.1 - - [18/May/2020 17:59:25] "[37mGET /create_database_dml HTTP/1.1[0m" 200 -
INFO:werkzeug: * Running on http://127.0.0.1:5000/ (Press CTRL+C to quit)
